Workbook

Sheet PM Tool Info Sheet
A1: Tool configuration I.D. | B1: Tool size (NPS) (in) | C1: Tool description | D1: Technology | E1: Tool type | F1: SF Item Describtion | G1: FSA Item Describtion | H1: FSA Alias | I1: Tool Body | J1: Days To Turn | K1: Data Logger Generation | L1: Nominal pipe OD (in) | M1: Min local bore (in) | N1: % DEF of OD | O1: Gauge plate size for line with <5D bends | P1: Gauge plate size for line with >5D bends | Q1: Min bend radius (multiples of pipe diameter) | R1: Min bore in 1.5D bends | S1: Min bore in 3D bends | T1: Min bore in 5D (or greater) bends | U1: Min dist. between bends (multiples of pipe diameter) | V1: Max tool velocity for sizing accuracy (ft/sec) | W1: Higher Specified Tool Velocity (ft/sec) | X1: Max wall thickness for MFL reporting accuracy at Higher Specified Tool Velocity (in) | Y1: Lower Specified Velocity (ft/sec) | Z1: Max wall thickness for MFL reporting accuracy at Lower Specified Tool Velocity (in) | AA1: Number of DEF sensors | AB1: Number of Flex MFL sensors | AC1: Number of GMFL sensors | AD1: Number of IDOD sensors | AE1: Number of K360 sensors | AF1: Number of LFM sensors | AG1: Number of LGT sensors | AH1: Number of MFL sensors | AI1: Number of RES sensors | AJ1: Number of SpirALL® MFL sensors | AK1: Number of UHR DEF sensors | AL1: Number of UHR MFL sensors | AM1: Number of Ultra Res MFL sensors | AN1: Max sampling rate (samp/sec) | AO1: Length standard config (in) | AP1: Length added for each additional battery pack (in) | AQ1: Tool weight (lb) | AR1: Weight added for each additional battery pack (lb) | AS1: Run time per alk pack (hours) | AT1: Run time per lith pack (hours) | AU1: Memory run time at 750 s/sec. (hours) | AV1: Total power (W) | AW1: Total current at 12 V supply (A) | AX1: Min pressure (psi) | AY1: Max pressure (psi) | AZ1: Specification document # | BA1: Ammonia compatible | BB1: Push in | BC1: Pull in | BD1: Vertical launch | BE1: Cassette | BF1: Strings / cell / nom volt alkaline | BG1: Strings / cell / nom volt lithium | BH1: In-Line Temperature Range (°F) | BI1: Launcher-Tool Performance Specification Dim 'A' (ft) | BJ1: Launcher-Tool Performance Specification Dim 'B' (ft) | BK1: Launcher-Tool Performance Specification Dim 'C' (ft) | BL1: Launcher-Tool Performance Specification Dim 'D' (in) | BM1: Launcher-Tool Performance Specification Dim 'E' (ft) | BN1: Launcher-Tool Performance Specification Dim 'F' (ft) | BO1: Receiver-Tool Performance Specification Dim 'A' (ft) | BP1: Receiver-Tool Performance Specification Dim 'B' (ft) | BQ1: Receiver-Tool Performance Specification Dim 'C' (ft) | BR1: Receiver-Tool Performance Specification Dim 'D' (in) | BS1: Receiver-Tool Performance Specification Dim 'E' (ft) | BT1: Receiver-Tool Performance Specification Dim 'F' (ft) | BU1: Min tool Launch/Receive Tray Height (in) | BV1: Max tool Launch/Receive Tray Height (in) | BW1: DRV | BX1: AMAG | BY1: DAA | BZ1: CPU | CA1: XMIT | CB1: BAT | CC1: BAT2 | CD1: SMAG | CE1: SMFL2 | CF1: EMAG | CG1: ARAA (RES) | CH1: LFM (LMAG) | CI1: GMAG | CJ1: Not for use in water | CK1: Count of Assets | CL1: Count TUL | CM1: Count SLC | CN1: Count HOU | CO1: Notes
A2: 115675 | B2: 4 | C2: 4" DEF NH3 | D2: Legacy | E2: DEF | G2: 4" DEF (NH3) | H2: DEF.04 | I2: =_xlfn.XLOOKUP(H2,'Alternative Tool Body Sheet'!A:A,'Alternative Tool Body Sheet'!C:C) -> 4 DEF | J2: =IF(ISNUMBER(SEARCH("Legacy",D2)),5, IF(OR(ISNUMBER(SEARCH("MDS",D2)),ISNUMBER(SEARCH("EMAT",D2))),7,"")) -> 5 | K2: Gen 3 | L2: 4.5 | M2: 3.5 | N2: 100 | P2: 3.875 | Q2: 3D | S2: 3.88 | U2: 3D | V2: 15 | AA2: 8 | AN2: 500 | AO2: 68 | AP2: 12 | AQ2: 52 | AR2: 10 | AT2: 10 | AV2: 3.1 | AW2: 0.26 | AX2: 375 | AY2: 2000 | AZ2: D2428 | BA2: YES | BB2: YES | BC2: YES | BD2: NO | BE2: NO | BF2: 1/6/9vdc | BG2: 1/6/21.6vdc | BH2: 14 to 131 | BI2: 6 | BJ2: 1 | BK2: 2 | BL2: 6 | BM2: 4 | BN2: 8 | BO2: 6 | BP2: 6 | BQ2: 2 | BR2: 6 | BS2: 4 | BT2: 8 | BY2: 04_610 | CJ2: FALSE | CT2: 115675 | CV2: DEF.04 | CW2: =TRIM(CV2) -> DEF.04
A3: 04_600 | B3: 4 | C3: 4" DEF - Liquid Products Only | D3: Legacy | E3: DEF | G3: 4" DEF | H3: DEF.04 | I3: =_xlfn.XLOOKUP(H3,'Alternative Tool Body Sheet'!A:A,'Alternative Tool Body Sheet'!C:C) -> 4 DEF | J3: =IF(ISNUMBER(SEARCH("Legacy",D3)),5, IF(OR(ISNUMBER(SEARCH("MDS",D3)),ISNUMBER(SEARCH("EMAT",D3))),7,"")) -> 5 | K3: Gen 3 | L3: 4.5 | M3: 3.5 | N3: 22.22 | P3: 3.875 | Q3: 3D | S3: 3.9 | T3: 3.7 | U3: 3D | V3: 15 | AA3: 8 | AN3: 500 | AO3: 61 | AP3: 12 | AQ3: 38 | AR3: 10 | AT3: 22 | AV3: 3.1 | AW3: 0.26 | AX3: 375 | AY3: 2000 | AZ3: D1018 | BA3: NO | BB3: YES | BC3: YES | BD3: NO | BE3: NO | BF3: 1/6/9vdc | BG3: 1/6/21.6vdc | BH3: 14 to 131 | BI3: 6 | BJ3: 1 | BK3: 2 | BL3: 6 | BM3: 4 | BN3: 8 | BO3: 6 | BP3: 6 | BQ3: 2 | BR3: 6 | BS3: 4 | BT3: 8 | BY3: 04_610 | CJ3: FALSE | CT3: 04_600 | CV3: DEF.04 | CW3: =TRIM(CV3) -> DEF.04
A4: 121771 | B4: 4 | C4: 4" DEF2 + IDOD | D4: Legacy | E4: DEF,IDOD | G4: 4" DEF2 + IDOD | H4: DEF.04 | I4: =_xlfn.XLOOKUP(H4,'Alternative Tool Body Sheet'!A:A,'Alternative Tool Body Sheet'!C:C) -> 4 DEF | J4: =IF(ISNUMBER(SEARCH("Legacy",D4)),5, IF(OR(ISNUMBER(SEARCH("MDS",D4)),ISNUMBER(SEARCH("EMAT",D4))),7,"")) -> 5 | K4: XHD | L4: 4.5 | M4: 3.5 | N4: 22.22 | O4: 4.25 | P4: 3.875 | Q4: 1.5D | R4: 3.86 | S4: 3.8 | T4: 3.75 | U4: 0D | V4: 15 | AA4: 16 | AD4: 16 | AN4: 750 | AO4: 43.9 | AQ4: 33.5 | AT4: 35 | AU4: 180000 | AV4: 1.4 | AW4: 0.097 | AX4: 300 | AY4: 2000 | AZ4: D2654 | BA4: NO | BB4: YES | BC4: YES | BD4: YES | BE4: NO | BF4: N/A | BG4: 4/0/14vdc | BH4: 14 to 131 | BI4: 4 | BJ4: 1 | BK4: 2 | BL4: 6 | BM4: 2 | BN4: 6 | BO4: 4 | BP4: 3 | BQ4: 2 | BR4: 6 | BS4: 2 | BT4: 6 | BU4: 12 | BY4: 04_610 | CJ4: TRUE | CT4: 121771 | CV4: DEF.04 | CW4: =TRIM(CV4) -> DEF.04
A5: 121770 | B5: 4 | C5: 4" MDS FLEX MFL2 + DEF2 | D5: MDS | E5: DEF,Flex MFL,IDOD | G5: 4" MDS FLEX MFL2+DEF2+IDOD | H5: FLEX.DEF.MFL.04 | I5: =_xlfn.XLOOKUP(H5,'Alternative Tool Body Sheet'!A:A,'Alternative Tool Body Sheet'!C:C) -> 4 MDS | J5: =IF(ISNUMBER(SEARCH("Legacy",D5)),5, IF(OR(ISNUMBER(SEARCH("MDS",D5)),ISNUMBER(SEARCH("EMAT",D5))),7,"")) -> 7 | K5: XHD | L5: 4.5 | M5: 3.6 | N5: 20 | P5: 3.875 | Q5: 1.5D | R5: 3.86 | S5: 3.75 | T5: 3.7 | U5: 0D | V5: 10 | W5: 10 | X5: 0.3 | Y5: 1 | Z5: 0.313 | AA5: 16 | AB5: 40 | AD5: 16 | AN5: 750 | AO5: 54.2 | AP5: 10.5 | AQ5: 48 | AR5: 8 | AT5: 38 | AU5: 180000 | AV5: 1.4 | AW5: 0.097 | AX5: 300 | AY5: 2000 | AZ5: D2481 | BA5: NO | BB5: YES | BC5: YES | BD5: YES | BE5: NO | BF5: 0/0/0vdc | BG5: 4/0/14vdc | BH5: 14 to 131 | BI5: 5 | BJ5: 1 | BK5: 2 | BL5: 6 | BM5: 4 | BN5: 7 | BO5: 5 | BP5: 5 | BQ5: 2 | BR5: 6 | BS5: 4 | BT5: 7 | BU5: 12 | BX5: 118211 | BY5: 116490 | CJ5: TRUE | CT5: 121770 | CV5: FLEX.DEF.MFL.04 | CW5: =TRIM(CV5) -> FLEX.DEF.MFL.04
A6: 115190 | B6: 4 | C6: 4" MFL NH3 | D6: Legacy | E6: MFL | G6: 4" MFL (NH3) | H6: MFL.04 | I6: =_xlfn.XLOOKUP(H6,'Alternative Tool Body Sheet'!A:A,'Alternative Tool Body Sheet'!C:C) -> 4 MFL | J6: =IF(ISNUMBER(SEARCH("Legacy",D6)),5, IF(OR(ISNUMBER(SEARCH("MDS",D6)),ISNUMBER(SEARCH("EMAT",D6))),7,"")) -> 5 | K6: Gen 3 | L6: 4.5 | M6: 3.6 | N6: 20 | P6: 3.875 | Q6: 3D | S6: 3.88 | T6: 3.7 | U6: 3D | V6: 10 | W6: 10 | X6: 0.25 | Y6: 1 | Z6: 0.343 | AH6: 24 | AN6: 500 | AO6: 69 | AP6: 12 | AQ6: 52 | AR6: 10 | AT6: 22 | AV6: 3.6 | AW6: 0.3 | AX6: 375 | AY6: 2000 | AZ6: D1385 | BA6: YES | BB6: YES | BC6: YES | BD6: NO | BE6: NO | BF6: 1/6/9vdc | BG6: 1/6/21.6vdc | BH6: 14 to 131 | BI6: 6 | BJ6: 1 | BK6: 2 | BL6: 6 | BM6: 4 | BN6: 8 | BO6: 6 | BP6: 6 | BQ6: 2 | BR6: 6 | BS6: 4 | BT6: 8 | BX6: 04_200 | CJ6: FALSE | CT6: 115190 | CV6: MFL.04 | CW6: =TRIM(CV6) -> MFL.04
A7: 04_001 | B7: 4 | C7: 4" MFL Liquid Products Only | D7: Legacy | E7: MFL | G7: 4" MFL | H7: MFL.04 | I7: =_xlfn.XLOOKUP(H7,'Alternative Tool Body Sheet'!A:A,'Alternative Tool Body Sheet'!C:C) -> 4 MFL | J7: =IF(ISNUMBER(SEARCH("Legacy",D7)),5, IF(OR(ISNUMBER(SEARCH("MDS",D7)),ISNUMBER(SEARCH("EMAT",D7))),7,"")) -> 5 | K7: Gen 3 | L7: 4.5 | M7: 3.6 | N7: 20 | P7: 3.875 | Q7: 3D | S7: 3.88 | T7: 3.7 | U7: 3D | V7: 10 | W7: 10 | X7: 0.25 | Y7: 1 | Z7: 0.343 | AH7: 24 | AN7: 500 | AO7: 63 | AP7: 12 | AQ7: 52 | AR7: 10 | AT7: 22 | AV7: 4.914 | AW7: 0.252 | AX7: 375 | AY7: 2000 | AZ7: D1020 | BA7: NO | BB7: YES | BC7: YES | BD7: NO | BE7: NO | BF7: 1/6/9vdc | BG7: 1/6/19.5vdc | BH7: 14 to 131 | BI7: 6 | BJ7: 1 | BK7: 2 | BL7: 6 | BM7: 4 | BN7: 8 | BO7: 6 | BP7: 6 | BQ7: 2 | BR7: 6 | BS7: 4 | BT7: 8 | BX7: 04_200 | CJ7: FALSE | CT7: 04_001 | CV7: MFL.04 | CW7: =TRIM(CV7) -> MFL.04
A8: 130095 | B8: 6 | C8: 6" MDS PRO DEF2+MFL4+SMFL+XYZ | D8: MDS | E8: DEF,IDOD,MFL,SpirALL® MFL,XYZ | G8: 6" MFL4+DEF2+SMFL+XYZ | H8: DEF.MFL.SMFL.XYZ.06 | I8: =_xlfn.XLOOKUP(H8,'Alternative Tool Body Sheet'!A:A,'Alternative Tool Body Sheet'!C:C) -> 6 MDS | J8: =IF(ISNUMBER(SEARCH("Legacy",D8)),5, IF(OR(ISNUMBER(SEARCH("MDS",D8)),ISNUMBER(SEARCH("EMAT",D8))),7,"")) -> 7 | K8: XHD | L8: 6.625 | M8: 5.5 | N8: 16.98 | P8: 5.75 | Q8: 1.5D | R8: 5.625 | S8: 5.56 | T8: 5.5 | U8: 3D | V8: 10 | W8: 10 | X8: 0.438 | Y8: 1 | Z8: 0.469 | AA8: 24 | AD8: 24 | AH8: 60 | AJ8: 160 | AN8: 750 | AO8: 101 | AP8: 13 | AQ8: 190 | AR8: 11 | AS8: 0 | AT8: 23 | AV8: 4 | AX8: 375 | AY8: 2000 | AZ8: D3712 | BA8: NO | BB8: NO | BC8: NO | BD8: NO | BE8: YES | BF8: N/A | BG8: 1/3/10.8vdc | BH8: 14 to 131 | BI8: 9 | BJ8: 1 | BK8: 2 | BL8: 8 | BM8: 4 | BN8: 12 | BO8: 9 | BP8: 9 | BQ8: 2 | BR8: 8 | BS8: 4 | BT8: 12 | BX8: 112174 | BY8: 112707 | CD8: 113045 | CJ8: TRUE | CT8: 130095 | CV8: DEF.MFL.SMFL.XYZ.06 | CW8: =TRIM(CV8) -> DEF.MFL.SMFL.XYZ.06
A9: 124750 | B9: 6 | C9: 6" MFL+DEF (xHD) | D9: Legacy | E9: DEF,IDOD,MFL | G9: 6" MFL+DEF (xHD) | H9: DEF.MFL.06 | I9: =_xlfn.XLOOKUP(H9,'Alternative Tool Body Sheet'!A:A,'Alternative Tool Body Sheet'!C:C) -> 6 DEF | J9: =IF(ISNUMBER(SEARCH("Legacy",D9)),5, IF(OR(ISNUMBER(SEARCH("MDS",D9)),ISNUMBER(SEARCH("EMAT",D9))),7,"")) -> 5 | K9: XHD | L9: 6.625 | M9: 5.46 | Q9: 3D | S9: 5.76 | U9: 3D | V9: 10 | W9: 10 | X9: 0.344 | Y9: 1 | Z9: 0.344 | AA9: 16 | AD9: 20 | AH9: 60 | AN9: 750 | AO9: 107 | AQ9: 130 | AT9: 132 | AW9: 0.88 | AX9: 375 | AY9: 2000 | AZ9: D3094 | BA9: NO | BB9: YES | BC9: YES | BD9: NO | BE9: NO | BF9: N/A | BG9: N/A | BH9: 14 to 131 | BI9: 9 | BJ9: 1 | BK9: 2 | BL9: 8 | BM9: 4 | BN9: 12 | BO9: 9 | BP9: 9 | BQ9: 2 | BR9: 8 | BS9: 4 | BT9: 12 | BX9: 06_201 | BY9: 06_6001 | CJ9: FALSE | CT9: 124750 | CV9: DEF.MFL.06 | CW9: =TRIM(CV9) -> DEF.MFL.06
A10: 129713 | B10: 6 | C10: 6" MDS FLEX DEF2+MFL4+XYZ | D10: MDS | E10: DEF,Flex MFL,IDOD,XYZ | G10: 6" MDS FLEX MFL4+DEF2+XYZ | H10: FLEX.DEF.MFL.XYZ.06 | I10: =_xlfn.XLOOKUP(H10,'Alternative Tool Body Sheet'!A:A,'Alternative Tool Body Sheet'!C:C) -> 6 MDS | J10: =IF(ISNUMBER(SEARCH("Legacy",D10)),5, IF(OR(ISNUMBER(SEARCH("MDS",D10)),ISNUMBER(SEARCH("EMAT",D10))),7,"")) -> 7 | K10: XHD | L10: 6.625 | M10: 5.5 | N10: 16.98 | O10: 5.75 | P10: 5.75 | Q10: 1.5D | R10: 5.625 | S10: 5.5 | T10: 5.5 | U10: 3D | V10: 10 | W10: 10 | X10: 0.438 | Y10: 1 | Z10: 0.469 | AA10: 24 | AB10: 60 | AD10: 24 | AN10: 750 | AO10: 74 | AP10: 13 | AQ10: 115 | AR10: 11 | AT10: 23 | AX10: 200 | AY10: 2000 | AZ10: D3713 | BA10: NO | BB10: NO | BC10: NO | BD10: NO | BE10: YES | BF10: N/A | BG10: N/A | BH10: 14 to 131 | BI10: 7 | BJ10: 1 | BK10: 2 | BL10: 8 | BM10: 4 | BN10: 9 | BO10: 7 | BP10: 7 | BQ10: 2 | BR10: 8 | BS10: 4 | BT10: 9 | BX10: 112174 | BY10: 112707 | CJ10: FALSE | CT10: 129713 | CV10: FLEX.DEF.MFL.XYZ.06 | CW10: =TRIM(CV10) -> FLEX.DEF.MFL.XYZ.06
A11: 06_6000 | B11: 6 | C11: 6" DEF | D11: Legacy | E11: DEF | G11: 6" DEF (1.5D) | H11: DEF.06 | I11: =_xlfn.XLOOKUP(H11,'Alternative Tool Body Sheet'!A:A,'Alternative Tool Body Sheet'!C:C) -> 6 DEF | J11: =IF(ISNUMBER(SEARCH("Legacy",D11)),5, IF(OR(ISNUMBER(SEARCH("MDS",D11)),ISNUMBER(SEARCH("EMAT",D11))),7,"")) -> 5 | K11: Gen 3 | L11: 6.625 | M11: 5.1 | N11: 23.02 | P11: 5.75 | Q11: 1.5D | R11: 5.76 | S11: 5.25 | T11: 5.1 | U11: 3D | V11: 15 | AA11: 16 | AN11: 500 | AO11: 95 | AP11: 19 | AQ11: 99 | AR11: 25 | AT11: 74 | AV11: 3.22 | AW11: 0.27 | AX11: 375 | AY11: 2000 | AZ11: D1021 | BA11: NO | BB11: YES | BC11: YES | BD11: NO | BE11: NO | BF11: 1/10/15vdc | BG11: 1/5/18vdc | BH11: 14 to 131 | BI11: 8 | BJ11: 1 | BK11: 2 | BL11: 8 | BM11: 4 | BN11: 10 | BO11: 8 | BP11: 8 | BQ11: 2 | BR11: 8 | BS11: 4 | BT11: 10 | BY11: 06_6001 | CJ11: FALSE | CT11: 06_6000 | CV11: DEF.06 | CW11: =TRIM(CV11) -> DEF.06
A12: 103829 | B12: 6 | C12: 6" LGT NH3 | D12: Legacy | E12: LGT | G12: 6" LGT Ammonia | H12: LGT.06 | I12: =_xlfn.XLOOKUP(H12,'Alternative Tool Body Sheet'!A:A,'Alternative Tool Body Sheet'!C:C) -> 6 LGT | J12: =IF(ISNUMBER(SEARCH("Legacy",D12)),5, IF(OR(ISNUMBER(SEARCH("MDS",D12)),ISNUMBER(SEARCH("EMAT",D12))),7,"")) -> 5 | K12: Gen 3 | L12: 6.625 | M12: 4.75 | N12: 28.3 | P12: 5.75 | Q12: 1.5D | R12: 5 | U12: 0D | V12: 15 | AG12: 8 | AN12: 750 | AO12: 87 | AP12: 16 | AQ12: 53 | AR12: 11 | AT12: 25 | AV12: 3.1 | AW12: 0.26 | AX12: 375 | AY12: 2000 | AZ12: D1675 | BA12: YES | BB12: NO | BC12: NO | BD12: NO | BE12: NO | BF12: N/A | BG12: 1/6/21.6vdc | BH12: 14 to 131 | BI12: 8 | BJ12: 1 | BK12: 2 | BL12: 8 | BM12: 4 | BN12: 10 | BO12: 8 | BP12: 8 | BQ12: 2 | BR12: 8 | BS12: 4 | BT12: 10 | BY12: 105683 | CJ12: FALSE | CT12: 103829 | CV12: LGT.06 | CW12: =TRIM(CV12) -> LGT.06
A13: 122434 | B13: 6 | C13: 6" MFL5 | D13: Legacy | E13: IDOD,MFL | G13: 6" MFL5 | H13: MFL.06 | I13: =_xlfn.XLOOKUP(H13,'Alternative Tool Body Sheet'!A:A,'Alternative Tool Body Sheet'!C:C) -> 6 MFL | J13: =IF(ISNUMBER(SEARCH("Legacy",D13)),5, IF(OR(ISNUMBER(SEARCH("MDS",D13)),ISNUMBER(SEARCH("EMAT",D13))),7,"")) -> 5 | K13: Gen 4 | L13: 6.625 | M13: 5.5 | O13: 5.75 | Q13: 1.5D | R13: 5.76 | U13: 0D | V13: 10 | W13: 10 | X13: 0.3 | Y13: 1 | Z13: 0.344 | AD13: 20 | AH13: 60 | AN13: 750 | AO13: 78 | AQ13: 100 | AT13: 46 | AX13: 375 | AY13: 2000 | AZ13: D2809 | BA13: NO | BB13: NO | BC13: NO | BD13: NO | BE13: NO | BF13: 1/10/15vdc | BG13: 1/5/18vdc | BH13: 14 to 131 | BI13: 7 | BJ13: 1 | BK13: 2 | BL13: 8 | BM13: 4 | BN13: 12 | BO13: 7 | BP13: 9 | BQ13: 2 | BR13: 8 | BS13: 4 | BT13: 12 | BX13: 06_201 | CJ13: FALSE | CT13: 122434 | CV13: MFL.06 | CW13: =TRIM(CV13) -> MFL.06
A14: 112200-01-00-01-01 | B14: 6 | C14: 6" MDS FLEX MFL4+DEF2 | D14: MDS | E14: DEF,Flex MFL,IDOD | G14: 6" MDS FLEX MFL4+DEF2 | H14: FLEX.DEF.MFL.06 | I14: =_xlfn.XLOOKUP(H14,'Alternative Tool Body Sheet'!A:A,'Alternative Tool Body Sheet'!C:C) -> 6 MDS | J14: =IF(ISNUMBER(SEARCH("Legacy",D14)),5, IF(OR(ISNUMBER(SEARCH("MDS",D14)),ISNUMBER(SEARCH("EMAT",D14))),7,"")) -> 7 | K14: XHD | L14: 6.625 | M14: 5.5 | N14: 16.98 | O14: 5.75 | P14: 5.75 | Q14: 1.5D | R14: 5.625 | S14: 5.5 | T14: 5.5 | U14: 3D | V14: 10 | W14: 10 | X14: 0.438 | Y14: 1 | Z14: 0.469 | AA14: 24 | AB14: 60 | AD14: 24 | AN14: 750 | AO14: 46 | AP14: 13 | AQ14: 76 | AR14: 11 | AT14: 97 | AX14: 200 | AY14: 2000 | AZ14: D2215 | BA14: NO | BB14: NO | BC14: NO | BD14: NO | BE14: YES | BF14: N/A | BG14: N/A | BH14: 14 to 131 | BI14: 4 | BJ14: 1 | BK14: 2 | BL14: 8 | BM14: 4 | BN14: 6 | BO14: 4 | BP14: 4 | BQ14: 2 | BR14: 8 | BS14: 4 | BT14: 6 | BX14: 112174 | BY14: 112707 | CJ14: TRUE | CT14: 112200-01-00-01-01 | CV14: FLEX.DEF.MFL.06 | CW14: =TRIM(CV14) -> FLEX.DEF.MFL.06
A15: 06_002 | B15: 6 | C15: 6" MFL NH3 | D15: Legacy | E15: MFL | G15: 6" MFL (NH3) | H15: MFL.06 | I15: =_xlfn.XLOOKUP(H15,'Alternative Tool Body Sheet'!A:A,'Alternative Tool Body Sheet'!C:C) -> 6 MFL | J15: =IF(ISNUMBER(SEARCH("Legacy",D15)),5, IF(OR(ISNUMBER(SEARCH("MDS",D15)),ISNUMBER(SEARCH("EMAT",D15))),7,"")) -> 5 | K15: Gen 4 | L15: 6.625 | M15: 5.46 | N15: 17.58 | P15: 5.75 | Q15: 3D | S15: 5.76 | T15: 5.64 | U15: 3D | V15: 10 | W15: 10 | X15: 0.344 | Y15: 1 | Z15: 0.344 | AH15: 60 | AN15: 500 | AO15: 97 | AP15: 19 | AQ15: 155 | AR15: 25 | AT15: 38 | AV15: 9.02 | AW15: 0.75 | AX15: 375 | AY15: 2000 | AZ15: D1028 | BA15: YES | BB15: YES | BC15: YES | BD15: NO | BE15: NO | BF15: 1/15/22.5vdc | BG15: 1/5/18vdc | BH15: 14 to 131 | BI15: 9 | BJ15: 1 | BK15: 2 | BL15: 8 | BM15: 4 | BN15: 12 | BO15: 9 | BP15: 9 | BQ15: 2 | BR15: 8 | BS15: 4 | BT15: 12 | BX15: 06_201 | CJ15: FALSE | CT15: 06_002 | CV15: MFL.06 | CW15: =TRIM(CV15) -> MFL.06
A16: 102783 | B16: 6 | C16: 6" DEF NH3 | D16: Legacy | E16: DEF | G16: 6" DEF (NH3) | H16: DEF.06 | I16: =_xlfn.XLOOKUP(H16,'Alternative Tool Body Sheet'!A:A,'Alternative Tool Body Sheet'!C:C) -> 6 DEF | J16: =IF(ISNUMBER(SEARCH("Legacy",D16)),5, IF(OR(ISNUMBER(SEARCH("MDS",D16)),ISNUMBER(SEARCH("EMAT",D16))),7,"")) -> 5 | K16: Gen 3 | L16: 6.625 | M16: 5.46 | N16: 17.58 | P16: 5.75 | Q16: 3D | S16: 5.76 | T16: 5.5 | U16: 3D | V16: 15 | AA16: 9 | AN16: 500 | AO16: 77 | AP16: 19 | AQ16: 85 | AR16: 25 | AT16: 107 | AV16: 3.22 | AW16: 0.27 | AX16: 375 | AY16: 2000 | AZ16: D1026 | BA16: YES | BB16: YES | BC16: YES | BD16: NO | BE16: NO | BF16: 1/10/15vdc | BG16: 1/5/18vdc | BH16: 14 to 131 | BI16: 7 | BJ16: 1 | BK16: 2 | BL16: 8 | BM16: 4 | BN16: 9 | BO16: 7 | BP16: 7 | BQ16: 2 | BR16: 8 | BS16: 4 | BT16: 9 | BY16: 102784 | CJ16: FALSE | CT16: 102783 | CV16: DEF.06 | CW16: =TRIM(CV16) -> DEF.06
A17: 112200-01-01-01-01 | B17: 6 | C17: 6" MFL4+DEF+SpirALL MFL | D17: MDS | E17: DEF,IDOD,MFL,SpirALL® MFL | G17: 6" MFL4+DEF2+SMFL | H17: DEF.MFL.SMFL.06 | I17: =_xlfn.XLOOKUP(H17,'Alternative Tool Body Sheet'!A:A,'Alternative Tool Body Sheet'!C:C) -> 6 MDS | J17: =IF(ISNUMBER(SEARCH("Legacy",D17)),5, IF(OR(ISNUMBER(SEARCH("MDS",D17)),ISNUMBER(SEARCH("EMAT",D17))),7,"")) -> 7 | K17: XHD | L17: 6.625 | M17: 5.5 | N17: 16.98 | P17: 5.75 | Q17: 1.5D | R17: 5.625 | S17: 5.56 | T17: 5.5 | U17: 3D | V17: 10 | W17: 10 | X17: 0.438 | Y17: 1 | Z17: 0.469 | AA17: 24 | AD17: 24 | AH17: 60 | AJ17: 160 | AN17: 750 | AO17: 73 | AP17: 13 | AQ17: 146 | AR17: 11 | AS17: 0 | AT17: 50 | AV17: 4 | AW17: 0.33 | AX17: 375 | AY17: 2000 | AZ17: D2084 | BA17: NO | BB17: NO | BC17: NO | BD17: NO | BE17: NO | BF17: 0/0/0vdc | BG17: 1/3/10.8vdc | BH17: 14 to 131 | BI17: 7 | BJ17: 1 | BK17: 2 | BL17: 8 | BM17: 4 | BN17: 9 | BO17: 7 | BP17: 7 | BQ17: 2 | BR17: 8 | BS17: 4 | BT17: 9 | BX17: 112174 | BY17: 112707 | CD17: 113045 | CJ17: TRUE | CT17: 112200-01-01-01-01 | CV17: DEF.MFL.SMFL.06 | CW17: =TRIM(CV17) -> DEF.MFL.SMFL.06
A18: 122975 | B18: 6 | C18: 6" DEF+XYZ | D18: Legacy | E18: DEF,XYZ | G18: 6" DEF+XYZ | H18: DEF.XYZ.06 | I18: =_xlfn.XLOOKUP(H18,'Alternative Tool Body Sheet'!A:A,'Alternative Tool Body Sheet'!C:C) -> 6 DEF | J18: =IF(ISNUMBER(SEARCH("Legacy",D18)),5, IF(OR(ISNUMBER(SEARCH("MDS",D18)),ISNUMBER(SEARCH("EMAT",D18))),7,"")) -> 5 | K18: Gen 3 | L18: 6.625 | M18: 5.1 | N18: 23.02 | P18: 5.75 | Q18: 1.5D | R18: 5.76 | S18: 5.25 | T18: 5.1 | U18: 3D | V18: 15 | AA18: 16 | AN18: 750 | AO18: 114 | AP18: 19 | AQ18: 108 | AR18: 25 | AT18: 23 | AV18: 12.21 | AW18: 0.872 | AX18: 375 | AY18: 2000 | AZ18: D2848 | BA18: NO | BB18: YES | BC18: YES | BD18: NO | BE18: NO | BF18: 1/10/15vdc | BG18: 1/5/18vdc | BH18: 14 to 131 | BI18: 10 | BJ18: 1 | BK18: 2 | BL18: 8 | BM18: 4 | BN18: 13 | BO18: 10 | BP18: 10 | BQ18: 2 | BR18: 8 | BS18: 4 | BT18: 13 | BY18: 06_6001 | CJ18: FALSE | CT18: 122975 | CV18: DEF.XYZ.06 | CW18: =TRIM(CV18) -> DEF.XYZ.06
A19: 106496 | B19: 6 | C19: 6" MFL3 (Hybrid)+XYZ | D19: Legacy | E19: IDOD,MFL,XYZ | G19: 6" MFL3 (Hybrid)+XYZ | H19: MFL.XYZ.06 | I19: =_xlfn.XLOOKUP(H19,'Alternative Tool Body Sheet'!A:A,'Alternative Tool Body Sheet'!C:C) -> 6 MFL | J19: =IF(ISNUMBER(SEARCH("Legacy",D19)),5, IF(OR(ISNUMBER(SEARCH("MDS",D19)),ISNUMBER(SEARCH("EMAT",D19))),7,"")) -> 5 | K19: Gen 4 | L19: 6.625 | M19: 5.46 | N19: 17.58 | P19: 5.75 | Q19: 1.5D | R19: 5.76 | T19: 5.64 | U19: 0D | V19: 10 | W19: 10 | X19: 0.375 | Y19: 1 | Z19: 0.375 | AD19: 20 | AH19: 60 | AN19: 750 | AO19: 96 | AP19: 16 | AQ19: 120 | AR19: 25 | AT19: 17 | AV19: 19 | AW19: 1.58 | AX19: 375 | AY19: 2000 | AZ19: D1581 | BA19: NO | BB19: NO | BC19: NO | BD19: NO | BE19: NO | BF19: 1/10/15vdc | BG19: 1/5/18vdc | BH19: 14 to 131 | BI19: 8 | BJ19: 1 | BK19: 2 | BL19: 8 | BM19: 4 | BN19: 10 | BO19: 8 | BP19: 8 | BQ19: 2 | BR19: 8 | BS19: 4 | BT19: 10 | BX19: 06_201 | CJ19: FALSE | CT19: 106496 | CV19: MFL.XYZ.06 | CW19: =TRIM(CV19) -> MFL.XYZ.06
A20: 119785 | B20: 6 | C20: 6" MFL+DEF | D20: Legacy | E20: DEF,IDOD,MFL | G20: 6" MFL+DEF | H20: DEF.MFL.06 | I20: =_xlfn.XLOOKUP(H20,'Alternative Tool Body Sheet'!A:A,'Alternative Tool Body Sheet'!C:C) -> 6 DEF | J20: =IF(ISNUMBER(SEARCH("Legacy",D20)),5, IF(OR(ISNUMBER(SEARCH("MDS",D20)),ISNUMBER(SEARCH("EMAT",D20))),7,"")) -> 5 | K20: Gen 4 | L20: 6.625 | M20: 5.46 | N20: 17.58 | P20: 5.75 | Q20: 3D | S20: 5.76 | U20: 3D | V20: 10 | W20: 10 | X20: 0.344 | Y20: 1 | Z20: 0.344 | AA20: 16 | AD20: 20 | AH20: 60 | AN20: 750 | AO20: 128 | AQ20: 165 | AT20: 47 | AV20: 10.5 | AW20: 0.88 | AX20: 375 | AY20: 2000 | AZ20: D1023 | BA20: NO | BB20: YES | BC20: YES | BD20: NO | BE20: NO | BF20: N/A | BG20: N/A | BH20: 14 to 131 | BI20: 11 | BJ20: 1 | BK20: 2 | BL20: 8 | BM20: 4 | BN20: 13 | BO20: 11 | BP20: 11 | BQ20: 2 | BR20: 8 | BS20: 4 | BT20: 13 | BX20: 06_201 | BY20: 06_6001 | CJ20: FALSE | CT20: 119785 | CV20: DEF.MFL.06 | CW20: =TRIM(CV20) -> DEF.MFL.06
A21: 129655 | B21: 6 | C21: 6" DEF+XYZ (xHD) | D21: Legacy | E21: DEF,XYZ | G21: 6" DEF+XYZ | H21: DEF.XYZ.06 | I21: =_xlfn.XLOOKUP(H21,'Alternative Tool Body Sheet'!A:A,'Alternative Tool Body Sheet'!C:C) -> 6 DEF | J21: =IF(ISNUMBER(SEARCH("Legacy",D21)),5, IF(OR(ISNUMBER(SEARCH("MDS",D21)),ISNUMBER(SEARCH("EMAT",D21))),7,"")) -> 5 | K21: XHD | L21: 6.625 | M21: 5.1 | N21: 23.02 | P21: 5.75 | Q21: 1.5D | R21: 5.76 | S21: 5.25 | T21: 5.1 | U21: 3D | V21: 15 | AA21: 16 | AN21: 750 | AO21: 111 | AP21: 19 | AQ21: 114 | AR21: 25 | AT21: 30 | AV21: 12.21 | AW21: 0.872 | AX21: 375 | AY21: 2000 | AZ21: D3696 | BA21: NO | BB21: YES | BC21: YES | BD21: NO | BE21: NO | BF21: N/A | BG21: N/A | BH21: 14 to 131 | BI21: 10 | BJ21: 1 | BK21: 2 | BL21: 8 | BM21: 4 | BN21: 13 | BO21: 10 | BP21: 10 | BQ21: 2 | BR21: 8 | BS21: 4 | BT21: 13 | BY21: 06_6001 | CJ21: FALSE | CT21: 129655 | CV21: DEF.XYZ.06 | CW21: =TRIM(CV21) -> DEF.XYZ.06
A22: 116837 | B22: 6 | C22: 6" MFL (xHD) | D22: Legacy | E22: IDOD,MFL | G22: 6" MFL (xHD) | H22: MFL.06 | I22: =_xlfn.XLOOKUP(H22,'Alternative Tool Body Sheet'!A:A,'Alternative Tool Body Sheet'!C:C) -> 6 MFL | J22: =IF(ISNUMBER(SEARCH("Legacy",D22)),5, IF(OR(ISNUMBER(SEARCH("MDS",D22)),ISNUMBER(SEARCH("EMAT",D22))),7,"")) -> 5 | K22: XHD | L22: 6.625 | M22: 5.46 | N22: 17.58 | P22: 5.75 | Q22: 3D | S22: 5.76 | T22: 5.64 | U22: 3D | V22: 10 | W22: 10 | X22: 0.344 | Y22: 1 | Z22: 0.344 | AD22: 20 | AH22: 60 | AN22: 750 | AO22: 92 | AP22: 19 | AQ22: 140 | AR22: 25 | AT22: 69 | AX22: 375 | AY22: 2000 | AZ22: D2847 | BA22: NO | BB22: YES | BC22: YES | BD22: NO | BE22: NO | BF22: 0/0/0vdc | BG22: 0/0/0vdc | BH22: 14 to 131 | BI22: 8 | BJ22: 1 | BK22: 2 | BL22: 8 | BM22: 4 | BN22: 10 | BO22: 8 | BP22: 8 | BQ22: 2 | BR22: 8 | BS22: 4 | BT22: 10 | BX22: 06_201 | CJ22: FALSE | CT22: 116837 | CV22: MFL.06 | CW22: =TRIM(CV22) -> MFL.06
A23: 127231 | B23: 6 | C23: 6" MFL+DEF+XYZ (xHD) | D23: Legacy | E23: DEF,IDOD,MFL,XYZ | G23: 6" MFL+DEF+XYZ (xHD) | H23: DEF.MFL.XYZ.06 | I23: 6 MFL | J23: =IF(ISNUMBER(SEARCH("Legacy",D23)),5, IF(OR(ISNUMBER(SEARCH("MDS",D23)),ISNUMBER(SEARCH("EMAT",D23))),7,"")) -> 5 | K23: XHD | L23: 6.625 | M23: 5.46 | Q23: 3D | S23: 5.76 | U23: 3D | V23: 10 | W23: 10 | X23: 0.344 | Y23: 1 | Z23: 0.344 | AA23: 16 | AD23: 20 | AH23: 60 | AN23: 750 | AO23: 127 | AQ23: 140 | AT23: 20 | AX23: 375 | AY23: 2000 | AZ23: D3240 | BA23: NO | BB23: NO | BC23: NO | BD23: NO | BE23: NO | BF23: N/A | BG23: N/A | BH23: 14 to 131 | BI23: 11 | BJ23: 1 | BK23: 2 | BL23: 8 | BM23: 4 | BN23: 14 | BO23: 11 | BP23: 11 | BQ23: 2 | BR23: 8 | BS23: 4 | BT23: 14 | BX23: 06_201 | CJ23: FALSE | CT23: 127231 | CV23: DEF.MFL.XYZ.06 | CW23: =TRIM(CV23) -> DEF.MFL.XYZ.06
A24: 119403 | B24: 6 | C24: 6" MFL5+XYZ | D24: Legacy | E24: IDOD,MFL,XYZ | G24: 6" MFL5+XYZ | H24: MFL.XYZ.06 | I24: =_xlfn.XLOOKUP(H24,'Alternative Tool Body Sheet'!A:A,'Alternative Tool Body Sheet'!C:C) -> 6 MFL | J24: =IF(ISNUMBER(SEARCH("Legacy",D24)),5, IF(OR(ISNUMBER(SEARCH("MDS",D24)),ISNUMBER(SEARCH("EMAT",D24))),7,"")) -> 5 | K24: Gen 4 | L24: 6.625 | M24: 5.5 | N24: 16.98 | P24: 5.75 | Q24: 1.5D | R24: 5.76 | T24: 5.64 | U24: 0D | V24: 10 | W24: 10 | X24: 0.3 | Y24: 1 | Z24: 0.344 | AD24: 20 | AH24: 60 | AN24: 750 | AO24: 96 | AP24: 16 | AQ24: 120 | AR24: 25 | AT24: 16 | AV24: 19 | AW24: 1.58 | AX24: 375 | AY24: 2000 | AZ24: D2532 | BA24: NO | BB24: NO | BC24: NO | BD24: NO | BE24: NO | BF24: 1/10/15vdc | BG24: 1/5/18vdc | BH24: 14 to 131 | BI24: 9 | BJ24: 1 | BK24: 2 | BL24: 8 | BM24: 4 | BN24: 12 | BO24: 9 | BP24: 9 | BQ24: 2 | BR24: 8 | BS24: 4 | BT24: 12 | BX24: 06_201 | CJ24: FALSE | CT24: 119403 | CV24: MFL.XYZ.06 | CW24: =TRIM(CV24) -> MFL.XYZ.06
A25: 112200-02-01-01-01 | B25: 6 | C25: 6" MFL4+DEF2+SpirALL MFL Dual Drive | D25: MDS | E25: DEF,IDOD,MFL,SpirALL® MFL | G25: 6" MFL4+DEF2+SpirALL® MFL Dual Drive | H25: DEF.MFL.SMFL.06 | I25: =_xlfn.XLOOKUP(H25,'Alternative Tool Body Sheet'!A:A,'Alternative Tool Body Sheet'!C:C) -> 6 MDS | J25: =IF(ISNUMBER(SEARCH("Legacy",D25)),5, IF(OR(ISNUMBER(SEARCH("MDS",D25)),ISNUMBER(SEARCH("EMAT",D25))),7,"")) -> 7 | K25: XHD | L25: 6.625 | M25: 5.5 | N25: 16.98 | P25: 5.75 | Q25: 1.5D | R25: 5.625 | S25: 5.56 | T25: 5.5 | U25: 3D | V25: 10 | X25: 0.438 | AA25: 24 | AD25: 24 | AH25: 60 | AJ25: 160 | AN25: 750 | AO25: 73 | AP25: 13 | AQ25: 146 | AR25: 11 | AT25: 70 | AV25: 4 | AW25: 0.33 | AX25: 375 | AY25: 2000 | BA25: NO | BB25: NO | BC25: NO | BD25: NO | BE25: NO | BF25: N/A | BG25: 1/3/10.8vdc | BH25: 14 to 131 | BI25: 7 | BJ25: 1 | BK25: 2 | BL25: 8 | BM25: 4 | BN25: 9 | BO25: 7 | BP25: 7 | BQ25: 2 | BR25: 8 | BS25: 4 | BT25: 9 | BX25: 112174 | BY25: 112707 | CD25: 113045 | CJ25: FALSE | CT25: 112200-02-01-01-01 | CV25: DEF.MFL.SMFL.06 | CW25: =TRIM(CV25) -> DEF.MFL.SMFL.06
A26: 113403 | B26: 6 | C26: 6" MFL+DEF NH3 | D26: Legacy | E26: DEF,MFL | G26: 6" MFL+DEF (NH3) | H26: DEF.MFL.06 | I26: =_xlfn.XLOOKUP(H26,'Alternative Tool Body Sheet'!A:A,'Alternative Tool Body Sheet'!C:C) -> 6 DEF | J26: =IF(ISNUMBER(SEARCH("Legacy",D26)),5, IF(OR(ISNUMBER(SEARCH("MDS",D26)),ISNUMBER(SEARCH("EMAT",D26))),7,"")) -> 5 | K26: Gen 4 | L26: 6.625 | M26: 5.46 | N26: 17.58 | P26: 5.75 | Q26: 3D | S26: 5.76 | U26: 3D | V26: 10 | W26: 10 | X26: 0.344 | Y26: 1 | Z26: 0.344 | AA26: 9 | AH26: 60 | AN26: 750 | AO26: 108 | AP26: 16 | AQ26: 165 | AR26: 25 | AT26: 31 | AV26: 11.22 | AW26: 0.94 | AX26: 375 | AY26: 2000 | AZ26: D2443 | BA26: YES | BB26: YES | BC26: YES | BD26: NO | BE26: NO | BF26: N/A | BG26: 1/5/18vdc | BH26: 14 to 131 | BI26: 9 | BJ26: 1 | BK26: 2 | BL26: 8 | BM26: 4 | BN26: 12 | BO26: 9 | BP26: 9 | BQ26: 2 | BR26: 8 | BS26: 4 | BT26: 12 | BX26: 06_201 | BY26: 102784 | CJ26: FALSE | CT26: 113403 | CV26: DEF.MFL.06 | CW26: =TRIM(CV26) -> DEF.MFL.06
A27: 105681 | B27: 6 | C27: 6" LGT | D27: Legacy | E27: LGT | G27: 6" LGT | H27: LGT.06 | I27: =_xlfn.XLOOKUP(H27,'Alternative Tool Body Sheet'!A:A,'Alternative Tool Body Sheet'!C:C) -> 6 LGT | J27: =IF(ISNUMBER(SEARCH("Legacy",D27)),5, IF(OR(ISNUMBER(SEARCH("MDS",D27)),ISNUMBER(SEARCH("EMAT",D27))),7,"")) -> 5 | K27: Gen 3 | L27: 6.625 | M27: 4.75 | N27: 28.3 | P27: 5.75 | Q27: 1.5D | R27: 5 | U27: 0D | V27: 15 | AG27: 8 | AN27: 500 | AO27: 88 | AP27: 16 | AQ27: 53 | AR27: 11 | AT27: 23 | AV27: 3.1 | AW27: 0.26 | AX27: 375 | AY27: 2000 | AZ27: D1402 | BA27: NO | BB27: NO | BC27: NO | BD27: NO | BE27: NO | BF27: N/A | BG27: 1/6/21.6vdc | BH27: 14 to 131 | BI27: 8 | BJ27: 1 | BK27: 2 | BL27: 8 | BM27: 4 | BN27: 10 | BO27: 8 | BP27: 8 | BQ27: 2 | BR27: 8 | BS27: 4 | BT27: 10 | BY27: 105683 | CJ27: FALSE | CT27: 105681 | CV27: LGT.06 | CW27: =TRIM(CV27) -> LGT.06
A28: 112200-01-01-02-01 | B28: 6 | C28: 6" MFL4+Brush DEF+SpirALL MFL | D28: MDS | E28: DEF,IDOD,MFL,SpirALL® MFL | G28: 6" MFL4+Brush DEF2+SpirALL® MFL | H28: DEF.MFL.SMFL.06 | I28: =_xlfn.XLOOKUP(H28,'Alternative Tool Body Sheet'!A:A,'Alternative Tool Body Sheet'!C:C) -> 6 MDS | J28: =IF(ISNUMBER(SEARCH("Legacy",D28)),5, IF(OR(ISNUMBER(SEARCH("MDS",D28)),ISNUMBER(SEARCH("EMAT",D28))),7,"")) -> 7 | K28: XHD | L28: 6.625 | M28: 5.5 | N28: 16.98 | P28: 5.75 | Q28: 1.5D | R28: 5.625 | S28: 5.56 | T28: 5.5 | U28: 3D | V28: 10 | W28: 10 | X28: 0.438 | Y28: 1 | Z28: 0.469 | AA28: 24 | AD28: 24 | AH28: 60 | AJ28: 160 | AN28: 750 | AO28: 73 | AP28: 13 | AQ28: 146 | AR28: 11 | AT28: 70 | AV28: 4 | AW28: 0.33 | AX28: 375 | AY28: 2000 | BA28: NO | BB28: NO | BC28: NO | BD28: NO | BE28: NO | BF28: N/A | BG28: 1/3/10.8vdc | BH28: 14 to 131 | BI28: 7 | BJ28: 1 | BK28: 2 | BL28: 8 | BM28: 4 | BN28: 9 | BO28: 7 | BP28: 7 | BQ28: 2 | BR28: 8 | BS28: 4 | BT28: 9 | BX28: 112174 | BY28: 112707 | CD28: 113045 | CJ28: TRUE | CT28: 112200-01-01-02-01 | CV28: DEF.MFL.SMFL.06 | CW28: =TRIM(CV28) -> DEF.MFL.SMFL.06
A29: 126981 | B29: 6 | C29: 6" DEF (xHD) | D29: Legacy | E29: DEF | G29: 6" DEF (xHD) | H29: DEF.06 | I29: =_xlfn.XLOOKUP(H29,'Alternative Tool Body Sheet'!A:A,'Alternative Tool Body Sheet'!C:C) -> 6 DEF | J29: =IF(ISNUMBER(SEARCH("Legacy",D29)),5, IF(OR(ISNUMBER(SEARCH("MDS",D29)),ISNUMBER(SEARCH("EMAT",D29))),7,"")) -> 5 | K29: XHD | L29: 6.625 | M29: 5.1 | Q29: 1.5D | R29: 5.76 | U29: 3D | V29: 15 | AA29: 16 | AN29: 750 | AO29: 89 | AQ29: 90 | AS29: 100 | AX29: 375 | AY29: 2000 | AZ29: D3242 | BA29: NO | BB29: NO | BC29: NO | BD29: NO | BE29: NO | BF29: N/A | BG29: N/A | BH29: 14 to 131 | BI29: 8 | BJ29: 1 | BK29: 2 | BL29: 8 | BM29: 4 | BN29: 10 | BO29: 8 | BP29: 8 | BQ29: 2 | BR29: 8 | BS29: 4 | BT29: 10 | BY29: 06_6001 | CJ29: FALSE | CT29: 126981 | CV29: DEF.06 | CW29: =TRIM(CV29) -> DEF.06
A30: 123925 | B30: 8 | C30: 8" MFL4+DEF+RES | D30: MDS | E30: DEF,Flex MFL,IDOD,RES | G30: 8" MDS FLEX MFL4+DEF+RES (V1) | H30: FLEX.DEF.MFL.RES.08 | I30: =_xlfn.XLOOKUP(H30,'Alternative Tool Body Sheet'!A:A,'Alternative Tool Body Sheet'!C:C) -> 8 MDS V1 | J30: =IF(ISNUMBER(SEARCH("Legacy",D30)),5, IF(OR(ISNUMBER(SEARCH("MDS",D30)),ISNUMBER(SEARCH("EMAT",D30))),7,"")) -> 7 | K30: XHD | L30: 8.625 | M30: 7.15 | P30: 7.625 | Q30: 1.5D | R30: 7.63 | S30: 7.4 | U30: 3D | V30: 10 | W30: 10 | X30: 0.4 | Y30: 1 | Z30: 0.412 | AA30: 36 | AB30: 72 | AD30: 36 | AI30: 72 | AN30: 750 | AO30: 70 | AQ30: 189 | AT30: 67 | AX30: 375 | AY30: 2000 | AZ30: D2906 | BA30: NO | BB30: NO | BC30: NO | BD30: NO | BE30: NO | BF30: N/A | BG30: N/A | BH30: 14 to 131 | BI30: 6 | BJ30: 1 | BK30: 2 | BL30: 10 | BM30: 4 | BN30: 8 | BO30: 6 | BP30: 6 | BQ30: 2 | BR30: 10 | BS30: 4 | BT30: 8 | BX30: 114560 | BY30: 110255 | CD30: 122013 | CJ30: FALSE | CT30: 123925 | CV30: FLEX.DEF.MFL.RES.08 | CW30: =TRIM(CV30) -> FLEX.DEF.MFL.RES.08
A31: 130593 | B31: 8 | C31: 8" MDS PRO DEF6+MFL6+RES+SMFL+XYZ | D31: MDS | E31: DEF,IDOD,MFL,RES,SpirALL® MFL,XYZ | G31: Pro 8" DEF+RES+SMFL+Ultra Res MFL+XYZ | H31: DEF.RES.SMFL.UMFL.XYZ.V1.08 | I31: 8 MDS V1 | J31: =IF(ISNUMBER(SEARCH("Legacy",D31)),5, IF(OR(ISNUMBER(SEARCH("MDS",D31)),ISNUMBER(SEARCH("EMAT",D31))),7,"")) -> 7 | K31: XHD | L31: 8.625 | M31: 7.15 | Q31: 3D | S31: 7.4 | U31: 3D | V31: 10 | W31: 10 | X31: 0.4 | Y31: 1 | Z31: 0.412 | AA31: 36 | AD31: 36 | AH31: 148 | AI31: 72 | AJ31: 180 | AN31: 750 | AO31: 128 | AQ31: 366 | AT31: 32 | AX31: 375 | AY31: 2000 | AZ31: D3761 | BA31: NO | BB31: YES | BC31: YES | BD31: NO | BE31: YES | BF31: N/A | BG31: N/A | BH31: 14 to 131 | BI31: 11 | BJ31: 1 | BK31: 2 | BL31: 10 | BM31: 4 | BN31: 14 | BO31: 11 | BP31: 11 | BQ31: 2 | BR31: 10 | BS31: 4 | BT31: 14 | BX31: 114560 | BY31: 110255 | CD31: 122013 | CJ31: FALSE | CT31: 130593 | CV31: DEF.RES.SMFL.UMFL.XYZ.V1.08 | CW31: =TRIM(CV31) -> DEF.RES.SMFL.UMFL.XYZ.V1.08
A32: 108563 | B32: 8 | C32: 8" DEF (xHD) | D32: Legacy | E32: DEF | G32: 8" DEF (xHD) | H32: DEF.08 | I32: =_xlfn.XLOOKUP(H32,'Alternative Tool Body Sheet'!A:A,'Alternative Tool Body Sheet'!C:C) -> 8 DEF | J32: =IF(ISNUMBER(SEARCH("Legacy",D32)),5, IF(OR(ISNUMBER(SEARCH("MDS",D32)),ISNUMBER(SEARCH("EMAT",D32))),7,"")) -> 5 | K32: XHD | L32: 8.625 | M32: 6.5 | N32: 24.64 | P32: 7.625 | Q32: 1.5D | R32: 7.125 | T32: 6.5 | U32: 3D | V32: 15 | AA32: 25 | AN32: 750 | AO32: 100 | AP32: 17 | AQ32: 200 | AR32: 35 | AT32: 77 | AX32: 375 | AY32: 2000 | AZ32: D1031 | BA32: NO | BB32: YES | BC32: YES | BD32: NO | BE32: NO | BF32: 1/12/18vdc | BG32: 1/6/21.6vdc | BH32: 14 to 131 | BI32: 9 | BJ32: 1 | BK32: 2 | BL32: 10 | BM32: 4 | BN32: 12 | BO32: 9 | BP32: 9 | BQ32: 2 | BR32: 10 | BS32: 4 | BT32: 12 | BY32: 108564 | CJ32: FALSE | CT32: 108563 | CV32: DEF.08 | CW32: =TRIM(CV32) -> DEF.08
A33: 123924 | B33: 8 | C33: 8" MFL4+DEF+SMFL+RES | D33: MDS | E33: DEF,IDOD,MFL,RES,SpirALL® MFL | G33: 8" MFL4+DEF+SMFL+RES (V1) | H33: DEF.MFL.RES.SMFL.08 | I33: =_xlfn.XLOOKUP(H33,'Alternative Tool Body Sheet'!A:A,'Alternative Tool Body Sheet'!C:C) -> 8 MDS V1 | J33: =IF(ISNUMBER(SEARCH("Legacy",D33)),5, IF(OR(ISNUMBER(SEARCH("MDS",D33)),ISNUMBER(SEARCH("EMAT",D33))),7,"")) -> 7 | K33: XHD | L33: 8.625 | M33: 7.15 | Q33: 3D | S33: 7.4 | U33: 3D | V33: 10 | W33: 10 | X33: 0.4 | Y33: 1 | Z33: 0.412 | AA33: 36 | AD33: 36 | AH33: 72 | AI33: 72 | AJ33: 180 | AN33: 750 | AO33: 90 | AQ33: 255 | AT33: 50 | AX33: 375 | AY33: 2000 | AZ33: D2930 | BA33: NO | BB33: NO | BC33: NO | BD33: NO | BE33: NO | BF33: N/A | BG33: N/A | BH33: 14 to 131 | BI33: 8 | BJ33: 1 | BK33: 2 | BL33: 10 | BM33: 4 | BN33: 10 | BO33: 8 | BP33: 8 | BQ33: 2 | BR33: 10 | BS33: 4 | BT33: 10 | BX33: 114560 | BY33: 110255 | CD33: 122013 | CJ33: FALSE | CT33: 123924 | CV33: DEF.MFL.RES.SMFL.08 | CW33: =TRIM(CV33) -> DEF.MFL.RES.SMFL.08
A34: 112056 | B34: 8 | C34: 8" GMFL (xHD) | D34: Legacy | E34: GMFL,IDOD | G34: 8" GMFL ATEX | H34: GMFL.08 | I34: =_xlfn.XLOOKUP(H34,'Alternative Tool Body Sheet'!A:A,'Alternative Tool Body Sheet'!C:C) -> 8 GMFL | J34: =IF(ISNUMBER(SEARCH("Legacy",D34)),5, IF(OR(ISNUMBER(SEARCH("MDS",D34)),ISNUMBER(SEARCH("EMAT",D34))),7,"")) -> 5 | K34: XHD | L34: 8.625 | M34: 6.9 | P34: 7.625 | Q34: 1.5D | R34: 7.5 | S34: 7 | T34: 7 | U34: 0D | V34: 10 | W34: 10 | X34: 0.471 | Y34: 1 | Z34: 0.53 | AC34: 72 | AD34: 24 | AN34: 750 | AO34: 89 | AP34: 17 | AQ34: 190 | AR34: 23 | AT34: 46 | AX34: 375 | AY34: 2000 | AZ34: D1200 | BA34: NO | BB34: NO | BC34: NO | BD34: NO | BE34: NO | BF34: 1/12/18vdc | BG34: 1/6/21.6vdc | BH34: 14 to 131 | BI34: 8 | BJ34: 1 | BK34: 2 | BL34: 10 | BM34: 4 | BN34: 10 | BO34: 8 | BP34: 8 | BQ34: 2 | BR34: 10 | BS34: 4 | BT34: 10 | CI34: 109401 | CJ34: FALSE | CT34: 112056 | CV34: GMFL.08 | CW34: =TRIM(CV34) -> GMFL.08
A35: 114353 | B35: 8 | C35: 8" DEF+XYZ (xHD) | D35: Legacy | E35: DEF,XYZ | G35: 8" DEF+XYZ (xHD) | H35: DEF.XYZ.08 | I35: =_xlfn.XLOOKUP(H35,'Alternative Tool Body Sheet'!A:A,'Alternative Tool Body Sheet'!C:C) -> 8 DEF | J35: =IF(ISNUMBER(SEARCH("Legacy",D35)),5, IF(OR(ISNUMBER(SEARCH("MDS",D35)),ISNUMBER(SEARCH("EMAT",D35))),7,"")) -> 5 | K35: XHD | L35: 8.625 | M35: 6.5 | N35: 24.64 | P35: 7.625 | Q35: 1.5D | R35: 7.13 | T35: 6.5 | U35: 3D | V35: 15 | AA35: 25 | AN35: 750 | AO35: 119 | AP35: 17 | AQ35: 235 | AR35: 23 | AT35: 18 | AX35: 375 | AY35: 2000 | AZ35: D2947 | BA35: NO | BB35: YES | BC35: YES | BD35: NO | BE35: NO | BF35: 0/0/0vdc | BG35: 0/0/0vdc | BH35: 14 to 131 | BI35: 10 | BJ35: 1 | BK35: 2 | BL35: 10 | BM35: 4 | BN35: 13 | BO35: 10 | BP35: 10 | BQ35: 2 | BR35: 10 | BS35: 4 | BT35: 13 | BY35: 108564 | CJ35: FALSE | CT35: 114353 | CV35: DEF.XYZ.08 | CW35: =TRIM(CV35) -> DEF.XYZ.08
A36: 106998 | B36: 8 | C36: 8" LGT+XYZ | D36: Legacy | E36: LGT,XYZ | G36: 8" LGT+XYZ | H36: LGT.XYZ.08 | I36: =_xlfn.XLOOKUP(H36,'Alternative Tool Body Sheet'!A:A,'Alternative Tool Body Sheet'!C:C) -> 8/10 LGT | J36: =IF(ISNUMBER(SEARCH("Legacy",D36)),5, IF(OR(ISNUMBER(SEARCH("MDS",D36)),ISNUMBER(SEARCH("EMAT",D36))),7,"")) -> 5 | K36: Gen 3 | L36: 8.625 | M36: 6 | N36: 44.93 | P36: 7.625 | Q36: 1.5D | R36: 7.13 | U36: 0D | V36: 15 | AG36: 19 | AN36: 750 | AO36: 81 | AP36: 19 | AQ36: 63 | AR36: 25 | AS36: 56 | AT36: 116 | AV36: 3.4 | AW36: 0.28 | AX36: 375 | AY36: 2000 | AZ36: D2253 | BA36: NO | BB36: YES | BC36: YES | BD36: NO | BE36: NO | BF36: 1/15/22.5vdc | BG36: 1/5/18vdc | BH36: 14 to 131 | BI36: 7 | BJ36: 1 | BK36: 2 | BL36: 10 | BM36: 4 | BN36: 9 | BO36: 7 | BP36: 7 | BQ36: 2 | BR36: 10 | BS36: 4 | BT36: 9 | BY36: 108564 | CJ36: FALSE | CT36: 106998 | CV36: LGT.XYZ.08 | CW36: =TRIM(CV36) -> LGT.XYZ.08
A37: 122503 | B37: 8 | C37: 8'' MFL5+DEF5+LFM | D37: MDS | E37: DEF,Flex MFL,IDOD,LFM | G37: 8" MDS FLEX MFL5+DEF5+LFM (V2) | H37: FLEX.DEF.LFM.MFL.08 | I37: =_xlfn.XLOOKUP(H37,'Alternative Tool Body Sheet'!A:A,'Alternative Tool Body Sheet'!C:C) -> 8 MDS V2 | J37: =IF(ISNUMBER(SEARCH("Legacy",D37)),5, IF(OR(ISNUMBER(SEARCH("MDS",D37)),ISNUMBER(SEARCH("EMAT",D37))),7,"")) -> 7 | K37: XHD | L37: 8.625 | M37: 7.045 | N37: 17.1 | P37: 7.625 | Q37: 1.5D | R37: 7.63 | U37: 3D | V37: 10 | W37: 10 | X37: 0.4 | Y37: 1 | Z37: 0.412 | AA37: 36 | AB37: 72 | AD37: 36 | AF37: 72 | AN37: 750 | AO37: 69.5 | AQ37: 201 | AT37: 67 | AX37: 375 | AY37: 2000 | AZ37: D2748 | BA37: NO | BB37: YES | BC37: YES | BD37: NO | BE37: YES | BF37: N/A | BG37: N/A | BH37: 14 to 131 | BI37: 7 | BJ37: 1 | BK37: 2 | BL37: 10 | BM37: 4 | BN37: 8 | BO37: 7 | BP37: 7 | BQ37: 2 | BR37: 10 | BS37: 4 | BT37: 8 | BX37: 121003 | BY37: 120927 | CD37: 121111 | CJ37: TRUE | CT37: 122503 | CV37: FLEX.DEF.LFM.MFL.08 | CW37: =TRIM(CV37) -> FLEX.DEF.LFM.MFL.08
A38: 130595 | B38: 8 | C38: 8" MDS FLEX DEF6+MFL6+RES+XYZ | D38: MDS | E38: DEF,IDOD,MFL,RES,XYZ | G38: 8" DEF+RES+Ultra Res MFL+XYZ 08" | H38: DEF.RES.UMFL.XYZ.V1.08 | I38: 8 MDS V1 | J38: =IF(ISNUMBER(SEARCH("Legacy",D38)),5, IF(OR(ISNUMBER(SEARCH("MDS",D38)),ISNUMBER(SEARCH("EMAT",D38))),7,"")) -> 7 | K38: XHD | L38: 8.625 | M38: 7.15 | Q38: 3D | S38: 7.4 | U38: 3D | V38: 10 | W38: 10 | X38: 0.4 | Y38: 1 | Z38: 0.412 | AA38: 36 | AD38: 36 | AH38: 148 | AI38: 72 | AN38: 750 | AO38: 106 | AQ38: 260 | AT38: 35 | AX38: 375 | AY38: 2000 | AZ38: D3763 | BA38: NO | BB38: YES | BC38: YES | BD38: NO | BE38: YES | BF38: N/A | BG38: N/A | BH38: 14 to 131 | BI38: 9 | BJ38: 1 | BK38: 2 | BL38: 10 | BM38: 4 | BN38: 12 | BO38: 9 | BP38: 9 | BQ38: 2 | BR38: 10 | BS38: 4 | BT38: 12 | BX38: 130501 | BY38: 110255 | CD38: 122013 | CJ38: FALSE | CT38: 130595 | CV38: DEF.RES.UMFL.XYZ.V1.08 | CW38: =TRIM(CV38) -> DEF.RES.UMFL.XYZ.V1.08
A39: 114418 | B39: 8 | C39: 8" MFL (1.5D ATEX) | D39: Legacy | E39: IDOD,MFL | G39: 8" MFL (1.5D) ATEX | H39: MFL.08 | I39: =_xlfn.XLOOKUP(H39,'Alternative Tool Body Sheet'!A:A,'Alternative Tool Body Sheet'!C:C) -> 8 MFL | J39: =IF(ISNUMBER(SEARCH("Legacy",D39)),5, IF(OR(ISNUMBER(SEARCH("MDS",D39)),ISNUMBER(SEARCH("EMAT",D39))),7,"")) -> 5 | K39: XHD | L39: 8.625 | M39: 7.15 | P39: 7.625 | Q39: 1.5D | R39: 7.63 | T39: 7.38 | U39: 3D | V39: 10 | X39: 0.438 | AD39: 24 | AH39: 72 | AN39: 750 | AO39: 101 | AQ39: 246 | AS39: 0 | AT39: 0 | AY39: 2000 | BA39: NO | BB39: YES | BC39: YES | BD39: NO | BE39: NO | BF39: 0/0/0vdc | BG39: 0/0/0vdc | BH39: 14 to 131 | BI39: 9 | BJ39: 1 | BK39: 2 | BL39: 10 | BM39: 4 | BN39: 12 | BO39: 9 | BP39: 9 | BQ39: 2 | BR39: 10 | BS39: 4 | BT39: 12 | BX39: 08_215 | CJ39: FALSE | CT39: 114418 | CV39: MFL.08 | CW39: =TRIM(CV39) -> MFL.08
A40: 130602 | B40: 8 | C40: 8" MDS FLEX DEF7+LFM+MFL6+XYZ | D40: MDS | E40: DEF,IDOD,LFM,MFL,XYZ | G40: MDS™ Flex DEF+LFM+Ultra Res MFL+XYZ 08" | H40: DEF.LFM.UMFL.XYZ.V2.08 | I40: 8 MDS V2 | J40: =IF(ISNUMBER(SEARCH("Legacy",D40)),5, IF(OR(ISNUMBER(SEARCH("MDS",D40)),ISNUMBER(SEARCH("EMAT",D40))),7,"")) -> 7 | K40: XHD | L40: 8.625 | M40: 7.045 | N40: 17.1 | P40: 7.625 | Q40: 1.5D | R40: 7.63 | U40: 3D | V40: 10 | W40: 10 | X40: 0.4 | Y40: 1 | Z40: 0.412 | AA40: 36 | AD40: 36 | AF40: 72 | AH40: 148 | AN40: 750 | AO40: 104 | AQ40: 301 | AT40: 35 | AX40: 375 | AY40: 2000 | AZ40: D3720 | BA40: NO | BB40: YES | BC40: YES | BD40: NO | BE40: YES | BF40: N/A | BG40: N/A | BH40: 14 to 131 | BI40: 9 | BJ40: 1 | BK40: 2 | BL40: 10 | BM40: 4 | BN40: 12 | BO40: 9 | BP40: 9 | BQ40: 2 | BR40: 10 | BS40: 4 | BT40: 12 | BX40: 130501 | BY40: 120927 | CD40: 121111 | CJ40: FALSE | CT40: 130602 | CV40: DEF.LFM.UMFL.XYZ.V2.08 | CW40: =TRIM(CV40) -> DEF.LFM.UMFL.XYZ.V2.08
...

Sheet IN FSA NOT PM SHEET
A1: Tool Config
A3: 123232 | B3: 6 | C3: 6" MFL3 | D3: Legacy | E3: IDOD,MFL | F3: Unreleased Configuration | G3: No Matching Tool Config
A4: 105191 | B4: 6 | C4: 6" MFL3 (Hybrid) | D4: Legacy | E4: IDOD,MFL | F4: Obsoleted | G4: No Matching Tool Config
A5: 124815 | B5: 6 | C5: 6" DEF+XYZ (ATEX) | D5: Legacy | E5: DEF,XYZ | F5: Unreleased Configuration | G5: No Matching Tool Config
A6: 124816 | B6: 6 | C6: 6" MFL3+XYZ (ATEX) | D6: Legacy | E6: IDOD,MFL,XYZ | F6: Unreleased Configuration | G6: No Matching Tool Config
A7: 106421-01 | B7: 30 | C7: 30" DEF+XYZ (xHD 106421-01) | D7: Legacy | E7: DEF,XYZ | F7: Obsoleted | G7: No Matching Tool Config | H7: No Matching Tool Config
A10: In FSA, NOT ON PM Sheet
A11: 113411 | B11: 6 | D11: Legacy | G11: =_xlfn.XLOOKUP(A11,'Just Methods'!T:T,'Just Methods'!S:S) -> 6" MFL2 | H11: =_xlfn.XLOOKUP(A11,'Just Methods'!T:T,'Just Methods'!C:C) -> MFL.06
A12: 116459 | B12: 6 | D12: Legacy | G12: =_xlfn.XLOOKUP(A12,'Just Methods'!T:T,'Just Methods'!S:S) -> 6" MFL3 ATEX | H12: =_xlfn.XLOOKUP(A12,'Just Methods'!T:T,'Just Methods'!C:C) -> MFL.06
A13: 116738 | B13: 6 | D13: Legacy | G13: =_xlfn.XLOOKUP(A13,'Just Methods'!T:T,'Just Methods'!S:S) -> 6" DEF ATEX | H13: =_xlfn.XLOOKUP(A13,'Just Methods'!T:T,'Just Methods'!C:C) -> DEF.06
A14: 129654 | B14: 6 | D14: Legacy | G14: =_xlfn.XLOOKUP(A14,'Just Methods'!T:T,'Just Methods'!S:S) -> 6" MFL+XYZ | H14: =_xlfn.XLOOKUP(A14,'Just Methods'!T:T,'Just Methods'!C:C) -> MFL.XYZ.06
A15: 129658 | B15: 6 | D15: Legacy | G15: =_xlfn.XLOOKUP(A15,'Just Methods'!T:T,'Just Methods'!S:S) -> 6" MFL (xHD) | H15: =_xlfn.XLOOKUP(A15,'Just Methods'!T:T,'Just Methods'!C:C) -> MFL.06
A16: 108323 | B16: 8 | D16: Legacy | G16: =_xlfn.XLOOKUP(A16,'Just Methods'!T:T,'Just Methods'!S:S) -> 8" DEF3 (Short) | H16: =_xlfn.XLOOKUP(A16,'Just Methods'!T:T,'Just Methods'!C:C) -> DEF.08
A17: 108472 | B17: 8 | D17: Legacy | G17: =_xlfn.XLOOKUP(A17,'Just Methods'!T:T,'Just Methods'!S:S) -> 8" GMFL (Short)- EH | H17: =_xlfn.XLOOKUP(A17,'Just Methods'!T:T,'Just Methods'!C:C) -> GMFL.08
A18: 110300 | B18: 8 | D18: Legacy | G18: =_xlfn.XLOOKUP(A18,'Just Methods'!T:T,'Just Methods'!S:S) -> 8" MFL BI-DI xHD | H18: =_xlfn.XLOOKUP(A18,'Just Methods'!T:T,'Just Methods'!C:C) -> MFL.08
A19: 124907 | B19: 8 | D19: MDS | G19: =_xlfn.XLOOKUP(A19,'Just Methods'!T:T,'Just Methods'!S:S) -> 8" Dual Drive SpirALL MFL+DEF+MFL4+RES | H19: =_xlfn.XLOOKUP(A19,'Just Methods'!T:T,'Just Methods'!C:C) -> DEF.MFL.RES.SMFL.08
A20: 108571 | B20: 10 | D20: Legacy | G20: =_xlfn.XLOOKUP(A20,'Just Methods'!T:T,'Just Methods'!S:S) -> 10" DEF (8" Batt) xHD | H20: =_xlfn.XLOOKUP(A20,'Just Methods'!T:T,'Just Methods'!C:C) -> DEF.10
A21: 115008 | B21: 10 | D21: Legacy | G21: =_xlfn.XLOOKUP(A21,'Just Methods'!T:T,'Just Methods'!S:S) -> 10" DEF+XYZ ATEX | H21: =_xlfn.XLOOKUP(A21,'Just Methods'!T:T,'Just Methods'!C:C) -> DEF.XYZ.10
A22: 117308 | B22: 10 | D22: Legacy | G22: =_xlfn.XLOOKUP(A22,'Just Methods'!T:T,'Just Methods'!S:S) -> 10" MFL+IDOD+DEF (NH3) | H22: =_xlfn.XLOOKUP(A22,'Just Methods'!T:T,'Just Methods'!C:C) -> DEF.MFL.10
... A47: 123170 | B47: 48 | D47: Legacy | G47: =_xlfn.XLOOKUP(A47,'Just Methods'!T:T,'Just Methods'!S:S) -> 48" GMFL+DEF | H47: =_xlfn.XLOOKUP(A47,'Just Methods'!T:T,'Just Methods'!C:C) -> DEF.GMFL.48
A50: 131428 | B50: 14 | C50: 14" MDS FLEX DEF+LFM+MFL3+XYZ | D50: MDS | E50: DEF,IDOD,LFM,MFL,XYZ | G50: No Matching Tool Config | I50: 0 | J50: 7 | K50: XHD | L50: 14 | M50: 11 | N50: 13.73 | P50: 11.25 | Q50: 1.5D | R50: 11.62 | U50: 3D | V50: 10 | W50: 10 | X50: 0.6 | Y50: 1 | Z50: 0.67 | AA50: 48 | AD50: 48 | AF50: 144 | AH50: 288 | AN50: 750 | AO50: 100 | AQ50: 563 | AT50: 21 | AV50: 25.52 | AW50: 2.13 | AX50: 375 | AY50: 2000 | AZ50: D3825 | BA50: NO | BB50: NO | BC50: YES | BD50: NO | BE50: YES | BF50: N/A | BG50: 0/0/21.6vdc | BH50: 14 to 131 | BI50: 9 | BJ50: 2 | BK50: 2 | BL50: 16 | BM50: 4 | BN50: 12 | BO50: 9 | BP50: 9 | BQ50: 2 | BR50: 16 | BS50: 4 | BT50: 12 | CJ50: FALSE | CT50: 131428
A51: 131429 | B51: 14 | C51: 14" MDS FLEX DEF+LFM+MFL3 | D51: MDS | E51: DEF,IDOD,LFM,MFL | G51: No Matching Tool Config | I51: 0 | J51: 7 | K51: XHD | L51: 14 | M51: 11 | N51: 13.73 | P51: 11.25 | Q51: 1.5D | R51: 11.62 | U51: 3D | V51: 10 | W51: 10 | X51: 0.6 | Y51: 1 | Z51: 0.67 | AA51: 48 | AD51: 48 | AF51: 144 | AH51: 288 | AN51: 750 | AO51: 100 | AQ51: 554 | AT51: 51 | AV51: 25.52 | AW51: 2.13 | AX51: 375 | AY51: 2000 | AZ51: D3826 | BA51: NO | BB51: NO | BC51: NO | BD51: NO | BE51: NO | BF51: N/A | BG51: 0/6/21.6vdc | BH51: 14 to 131 | BI51: 9 | BJ51: 2 | BK51: 2 | BL51: 16 | BM51: 4 | BN51: 12 | BO51: 9 | BP51: 9 | BQ51: 2 | BR51: 16 | BS51: 4 | BT51: 12 | CJ51: FALSE | CT51: 131429
A52: 131430 | B52: 14 | C52: 14" MDS FLEX DEF+MFL3+XYZ | D52: MDS | E52: DEF,IDOD,MFL,XYZ | G52: No Matching Tool Config | I52: 0 | J52: 7 | K52: XHD | L52: 14 | M52: 11 | N52: 13.73 | P52: 11.25 | Q52: 1.5D | R52: 11.62 | U52: 3D | V52: 10 | W52: 10 | X52: 0.6 | Y52: 1 | Z52: 0.67 | AA52: 48 | AD52: 48 | AH52: 288 | AN52: 750 | AO52: 100 | AQ52: 489 | AT52: 22 | AV52: 25.52 | AW52: 2.13 | AX52: 375 | AY52: 2000 | AZ52: D3827 | BA52: NO | BB52: NO | BC52: YES | BD52: NO | BE52: YES | BF52: N/A | BG52: 0/6/21.6vdc | BH52: 14 to 131 | BI52: 9 | BJ52: 2 | BK52: 2 | BL52: 16 | BM52: 4 | BN52: 12 | BO52: 9 | BP52: 9 | BQ52: 2 | BR52: 16 | BS52: 4 | BT52: 12 | CJ52: FALSE | CT52: 131430
A53: 109000 | B53: 16 | C53: 16" MFL2+DEF2+SMFL2+XYZ+LFM | D53: MDS | E53: DEF,IDOD,LFM,MFL,SpirALL® MFL,XYZ | G53: No Matching Tool Config | I53: 0 | J53: 7 | K53: XHD | L53: 16 | M53: 13.6 | N53: 15 | P53: 15 | Q53: 1.5D | R53: 14.5 | U53: 3D | V53: 10 | W53: 10 | X53: 0.625 | Y53: 1 | Z53: 0.625 | AA53: 60 | AD53: 60 | AF53: 180 | AH53: 180 | AJ53: 396 | AN53: 750 | AO53: 144 | AQ53: 1383 | AT53: 15 | AV53: 27.52 | AW53: 2.29 | AX53: 375 | AY53: 2000 | AZ53: D2043 | BA53: NO | BB53: NO | BC53: NO | BD53: NO | BE53: NO | BF53: N/A | BG53: 3/6/21.6vdc | BH53: 14 to 131 | BI53: 12 | BJ53: 2 | BK53: 2 | BL53: 18 | BM53: 4 | BN53: 15 | BO53: 12 | BP53: 12 | BQ53: 2 | BR53: 18 | BS53: 4 | BT53: 15 | BY53: 109845 | CJ53: FALSE | CT53: 109000
A54: 131431 | B54: 14 | C54: 14" MDS FLEX DEF+MFL3 | D54: MDS | E54: DEF,IDOD,MFL | G54: No Matching Tool Config | I54: 0 | J54: 7 | K54: XHD | L54: 14 | M54: 11 | N54: 13.73 | P54: 11.25 | Q54: 1.5D | R54: 11.62 | U54: 3D | V54: 10 | W54: 10 | X54: 0.6 | Y54: 1 | Z54: 0.67 | AA54: 48 | AD54: 48 | AH54: 288 | AN54: 750 | AO54: 100 | AQ54: 480 | AT54: 64 | AV54: 25.52 | AW54: 2.13 | AX54: 375 | AY54: 2000 | AZ54: D3828 | BA54: NO | BB54: NO | BC54: YES | BD54: NO | BE54: YES | BF54: N/A | BG54: 0/6/21.6vdc | BH54: 14 to 131 | BI54: 9 | BJ54: 2 | BK54: 2 | BL54: 16 | BM54: 4 | BN54: 12 | BO54: 9 | BP54: 9 | BQ54: 2 | BR54: 16 | BS54: 4 | BT54: 12 | CJ54: FALSE | CT54: 131431

Sheet Tool Body Components
A1: Size | B1: Tool Componet | C1: Model Number | D1: Technogolgy | E1: Other Name | F1: Notes | G1: Dual Size
A2: 4 | B2: DEF | C2: 04_610 | D2: Legacy | E2: DAA
A3: 4 | B3: MFL | C3: 04_200 | D3: Legacy | E3: AMAG
A4: 4 | B4: MFL | C4: 118211 | D4: MDS | E4: AMAG
A5: 4 | B5: DEF | C5: 116490 | D5: MDS | E5: DAA
A6: 6 | B6: DEF | C6: 06_6001 | D6: Legacy | E6: DAA
A7: 6 | B7: MFL | C7: 06_201 | D7: Legacy | E7: AMAG | F7: MLF5
A8: 6 | B8: LGT | C8: 105683 | D8: Legacy | E8: DAA | F8: DEF
A9: 6 | B9: MFL | C9: 112174 | D9: MDS | E9: AMAG
A10: 6 | B10: SMFL | C10: 113045 | D10: MDS | E10: SMAG
A11: 6 | B11: DEF | C11: 112707 | D11: MDS | E11: DAA
A12: 6 | B12: MFL | C12: 06_201 | D12: Legacy | E12: AMAG | F12: NH3
A13: 6 | B13: DEF | C13: 102784 | D13: Legacy | E13: DAA | F13: NH3
A14: 8 | B14: DEF | C14: 108564 | D14: Legacy | E14: DAA
A15: 8 | B15: GMFL | C15: 109401 | D15: Legacy | E15: GMAG
A16: 8 | B16: MFL | C16: 08_215 | D16: Legacy | E16: AMAG
A17: 8 | B17: MFL | C17: 114560 | D17: MDS | E17: AMAG | F17: V1
A18: 8 | B18: MFL | C18: 130501 | D18: MDS | E18: AMAG | F18: V1, UR
A19: 8 | B19: SMFL | C19: 122013 | D19: MDS | E19: SMAG | F19: V1
A20: 8 | B20: DEF | C20: 110255 | D20: MDS | E20: DAA | F20: V1
A21: 8 | B21: MFL | C21: 121003 | D21: MDS | E21: AMAG | F21: V2
A22: 8 | B22: DEF | C22: 120927 | D22: MDS | E22: DAA | F22: V2
A23: 8 | B23: SMFL | C23: 121111 | D23: MDS | E23: SMAG | F23: V2
A24: 8 | B24: MFL | C24: 130501 | D24: MDS | E24: MFL | F24: V2, UR | H24: UR
A25: 8/10 | B25: LGT | C25: 112179 | D25: Legacy | E25: DAA | F25: LGT | G25: 8, 10
A26: 8 | B26: DEF | C26: 107269 | D26: Legacy | E26: DAA | F26: NH3
A27: 8 | B27: MFL | C27: 08_215 | D27: Legacy | E27: AMAG | F27: NH3
A28: 10 | B28: DEF | C28: 112058 | D28: Legacy | E28: DAA
A29: 10 | B29: MFL | C29: 10_201 | D29: Legacy | E29: AMAG
A30: 10 | B30: GMFL | C30: 108557 | D30: Legacy | E30: GMAG
A31: 10 | B31: GDEF | C31: 113727 | D31: Legacy | E31: GDAA
A32: 10 | B32: MFL | C32: 108081 | D32: MDS | E32: AMAG
A33: 10 | B33: MFL | C33: 130285 | D33: MDS | E33: AMAG | F33: UR
A34: 10 | B34: DEF | C34: 110257 | D34: MDS | E34: DAA
A35: 10 | B35: SMFL | C35: 123689 | D35: MDS | E35: SMAG
A36: 10 | B36: MFL | C36: 10_201 | D36: Legacy | E36: AMAG | F36: NH3
A37: 10 | B37: DEF | C37: 112058 | D37: Legacy | E37: DAA | F37: NH3
A38: 10 | B38: EMAT | C38: 111201 | D38: EMAT | E38: EMAG
A39: 12 | B39: DEF | C39: 112106 | D39: Legacy | E39: DAA
A40: 12 | B40: MFL | C40: 12_201 | D40: Legacy | E40: AMAG
...

Sheet Just Methods
A1: Type | B1: Name | C1: Alias | D1: Company Structure | E1: Modified On | F1: Event And Detail | G1: Quantity | H1: Resource Event Type | I1: Resource ID | J1: Service Object | K1: Status | L1: Template | M1: Tool Config | N1: Long Name | O1: Mapping | P1: Size | S1: Long Name | T1: Tool Config
A2: Method | B2: 115190, 4" MFL (NH3) | C2: MFL.04 | D2: TD Williamson, Inc | E2: 4/17/2023 1:37:42 PM | F2: Available | G2: 1 | H2: Available | I2: 94388 | J2: No | K2: Available | L2: Yes | M2: =_xlfn.TEXTBEFORE(B2, ",") -> 115190 | N2: =_xlfn.TEXTAFTER(B2, ",") -> 4" MFL (NH3) | O2: =ISNUMBER(SEARCH("xyz", B2)) -> FALSE | S2: 4" MFL (NH3) | T2: 115190
A3: Method | B3: 04_001, 4" MFL | C3: MFL.04 | D3: TD Williamson, Inc | E3: 4/17/2023 1:42:37 PM | F3: Available | G3: 1 | H3: Available | I3: 94407 | J3: No | K3: Available | L3: Yes | M3: =_xlfn.TEXTBEFORE(B3, ",") -> 04_001 | N3: =_xlfn.TEXTAFTER(B3, ",") -> 4" MFL | O3: =ISNUMBER(SEARCH("xyz", B3)) -> FALSE | S3: 4" MFL | T3: 04_001
A4: Method | B4: 04_600, 4" DEF | C4: DEF.04 | D4: TD Williamson, Inc | E4: 4/17/2023 1:43:34 PM | F4: Available | G4: 1 | H4: Available | I4: 94408 | J4: No | K4: Available | L4: Yes | M4: =_xlfn.TEXTBEFORE(B4, ",") -> 04_600 | N4: =_xlfn.TEXTAFTER(B4, ",") -> 4" DEF | O4: =ISNUMBER(SEARCH("xyz", B4)) -> FALSE | S4: 4" DEF | T4: 04_600
A5: Method | B5: 115675, 4" DEF (NH3) | C5: DEF.04 | D5: TD Williamson, Inc | E5: 6/7/2017 5:09:02 PM | F5: Available | G5: 1 | H5: Available | I5: 94807 | J5: No | K5: Available | L5: Yes | M5: =_xlfn.TEXTBEFORE(B5, ",") -> 115675 | N5: =_xlfn.TEXTAFTER(B5, ",") -> 4" DEF (NH3) | O5: =ISNUMBER(SEARCH("xyz", B5)) -> FALSE | S5: 4" DEF (NH3) | T5: 115675
A6: Method | B6: 121771, 4" DEF2 + IDOD | C6: DEF.04 | D6: TD Williamson, Inc | E6: 4/17/2023 1:39:55 PM | F6: Available | G6: 1 | H6: Available | I6: 97556 | J6: No | K6: Available | L6: Yes | M6: =_xlfn.TEXTBEFORE(B6, ",") -> 121771 | N6: =_xlfn.TEXTAFTER(B6, ",") -> 4" DEF2 + IDOD | O6: =ISNUMBER(SEARCH("xyz", B6)) -> FALSE | S6: 4" DEF2 + IDOD | T6: 121771
A7: Method | B7: 121770, 4" MDS FLEX MFL2+DEF2+IDOD | C7: FLEX.DEF.MFL.04 | D7: TD Williamson, Inc | E7: 4/17/2023 1:40:10 PM | F7: Available | G7: 1 | H7: Available | I7: 97557 | J7: No | K7: Available | L7: Yes | M7: =_xlfn.TEXTBEFORE(B7, ",") -> 121770 | N7: =_xlfn.TEXTAFTER(B7, ",") -> 4" MDS FLEX MFL2+DEF2+IDOD | O7: =ISNUMBER(SEARCH("xyz", B7)) -> FALSE | S7: 4" MDS FLEX MFL2+DEF2+IDOD | T7: 121770
A8: Method | B8: 102783, 6" DEF (NH3) | C8: DEF.06 | D8: TD Williamson, Inc | E8: 6/14/2017 9:36:19 AM | F8: Available | G8: 1 | H8: Available | I8: 94039 | J8: No | K8: Available | L8: Yes | M8: =_xlfn.TEXTBEFORE(B8, ",") -> 102783 | N8: =_xlfn.TEXTAFTER(B8, ",") -> 6" DEF (NH3) | O8: =ISNUMBER(SEARCH("xyz", B8)) -> FALSE | S8: 6" DEF (NH3) | T8: 102783
A9: Method | B9: 106496, 6" MFL3 (Hybrid)+XYZ | C9: MFL.XYZ.06 | D9: TD Williamson, Inc | E9: 4/17/2023 1:48:51 PM | F9: Available | G9: 1 | H9: Available | I9: 94109 | J9: No | K9: Available | L9: Yes | M9: =_xlfn.TEXTBEFORE(B9, ",") -> 106496 | N9: =_xlfn.TEXTAFTER(B9, ",") -> 6" MFL3 (Hybrid)+XYZ | O9: =ISNUMBER(SEARCH("xyz", B9)) -> TRUE | S9: 6" MFL3 (Hybrid)+XYZ | T9: 106496
A10: Method | B10: 112200-02-01-01-01, 6" MFL4+DEF2+SpirALL® MFL Dual Drive | C10: DEF.MFL.SMFL.06 | D10: TD Williamson, Inc | E10: 4/24/2023 3:55:36 PM | F10: Available | G10: 1 | H10: Available | I10: 94306 | J10: No | K10: Available | L10: Yes | M10: =_xlfn.TEXTBEFORE(B10, ",") -> 112200-02-01-01-01 | N10: =_xlfn.TEXTAFTER(B10, ",") -> 6" MFL4+DEF2+SpirALL® MFL Dual Drive | O10: =ISNUMBER(SEARCH("xyz", B10)) -> FALSE | S10: 6" MFL4+DEF2+SpirALL® MFL Dual Drive | T10: 112200-02-01-01-01
A11: Method | B11: 113403, 6" MFL+DEF (NH3) | C11: DEF.MFL.06 | D11: TD Williamson, Inc | E11: 4/17/2023 1:49:16 PM | F11: Available | G11: 1 | H11: Available | I11: 94315 | J11: No | K11: Available | L11: Yes | M11: =_xlfn.TEXTBEFORE(B11, ",") -> 113403 | N11: =_xlfn.TEXTAFTER(B11, ",") -> 6" MFL+DEF (NH3) | O11: =ISNUMBER(SEARCH("xyz", B11)) -> FALSE | S11: 6" MFL+DEF (NH3) | T11: 113403
A12: Method | B12: 113411, 6" MFL2 | C12: MFL.06 | D12: TD Williamson, Inc | E12: 4/24/2023 3:43:40 PM | F12: Available | G12: 1 | H12: Available | I12: 94317 | J12: No | K12: Available | L12: Yes | M12: =_xlfn.TEXTBEFORE(B12, ",") -> 113411 | N12: =_xlfn.TEXTAFTER(B12, ",") -> 6" MFL2 | O12: =ISNUMBER(SEARCH("xyz", B12)) -> FALSE | S12: 6" MFL2 | T12: 113411
A13: Method | B13: 116459, 6" MFL3 ATEX | C13: MFL.06 | D13: TD Williamson, Inc | E13: 4/24/2023 3:45:22 PM | F13: Available | G13: 1 | H13: Available | I13: 94393 | J13: No | K13: Available | L13: Yes | M13: =_xlfn.TEXTBEFORE(B13, ",") -> 116459 | N13: =_xlfn.TEXTAFTER(B13, ",") -> 6" MFL3 ATEX | O13: =ISNUMBER(SEARCH("xyz", B13)) -> FALSE | S13: 6" MFL3 ATEX | T13: 116459
A14: Method | B14: 116738, 6" DEF ATEX | C14: DEF.06 | D14: TD Williamson, Inc | E14: 4/24/2023 3:37:16 PM | F14: Available | G14: 1 | H14: Available | I14: 94396 | J14: No | K14: Available | L14: Yes | M14: =_xlfn.TEXTBEFORE(B14, ",") -> 116738 | N14: =_xlfn.TEXTAFTER(B14, ",") -> 6" DEF ATEX | O14: =ISNUMBER(SEARCH("xyz", B14)) -> FALSE | S14: 6" DEF ATEX | T14: 116738
A15: Method | B15: 116837, 6" MFL (xHD) | C15: MFL.06 | D15: TD Williamson, Inc | E15: 1/10/2024 11:41:11 AM | F15: Available | G15: 1 | H15: Available | I15: 94398 | J15: No | K15: Available | L15: Yes | M15: =_xlfn.TEXTBEFORE(B15, ",") -> 116837 | N15: =_xlfn.TEXTAFTER(B15, ",") -> 6" MFL (xHD) | O15: =ISNUMBER(SEARCH("xyz", B15)) -> FALSE | S15: 6" MFL (xHD) | T15: 116837
A16: Method | B16: 06_002, 6" MFL (NH3) | C16: MFL.06 | D16: TD Williamson, Inc | E16: 4/17/2023 1:59:17 PM | F16: Available | G16: 1 | H16: Available | I16: 94409 | J16: No | K16: Available | L16: Yes | M16: =_xlfn.TEXTBEFORE(B16, ",") -> 06_002 | N16: =_xlfn.TEXTAFTER(B16, ",") -> 6" MFL (NH3) | O16: =ISNUMBER(SEARCH("xyz", B16)) -> FALSE | S16: 6" MFL (NH3) | T16: 06_002
A17: Method | B17: 06_6000, 6" DEF (1.5D) | C17: DEF.06 | D17: TD Williamson, Inc | E17: 4/17/2023 2:02:52 PM | F17: Available | G17: 1 | H17: Available | I17: 94410 | J17: No | K17: Available | L17: Yes | M17: =_xlfn.TEXTBEFORE(B17, ",") -> 06_6000 | N17: =_xlfn.TEXTAFTER(B17, ",") -> 6" DEF (1.5D) | O17: =ISNUMBER(SEARCH("xyz", B17)) -> FALSE | S17: 6" DEF (1.5D) | T17: 06_6000
A18: Method | B18: 112200-01-01-02-01, 6" MFL4+Brush DEF2+SpirALL® MFL | C18: DEF.MFL.SMFL.06 | D18: TD Williamson, Inc | E18: 4/24/2023 3:56:07 PM | F18: Available | G18: 1 | H18: Available | I18: 94423 | J18: No | K18: Available | L18: Yes | M18: =_xlfn.TEXTBEFORE(B18, ",") -> 112200-01-01-02-01 | N18: =_xlfn.TEXTAFTER(B18, ",") -> 6" MFL4+Brush DEF2+SpirALL® MFL | O18: =ISNUMBER(SEARCH("xyz", B18)) -> FALSE | S18: 6" MFL4+Brush DEF2+SpirALL® MFL | T18: 112200-01-01-02-01
A19: Method | B19: 112200-01-01-01-01, 6" MFL4+DEF2+SMFL | C19: DEF.MFL.SMFL.06 | D19: TD Williamson, Inc | E19: 5/23/2025 9:19:56 AM | F19: Available | G19: 1 | H19: Available | I19: 94424 | J19: No | K19: Available | L19: Yes | M19: =_xlfn.TEXTBEFORE(B19, ",") -> 112200-01-01-01-01 | N19: =_xlfn.TEXTAFTER(B19, ",") -> 6" MFL4+DEF2+SMFL | O19: =ISNUMBER(SEARCH("xyz", B19)) -> FALSE | S19: 6" MFL4+DEF2+SMFL | T19: 112200-01-01-01-01
A20: Method | B20: 119403, 6" MFL5+XYZ | C20: MFL.XYZ.06 | D20: TD Williamson, Inc | E20: 4/17/2023 1:50:27 PM | F20: Available | G20: 1 | H20: Available | I20: 94531 | J20: No | K20: Available | L20: Yes | M20: =_xlfn.TEXTBEFORE(B20, ",") -> 119403 | N20: =_xlfn.TEXTAFTER(B20, ",") -> 6" MFL5+XYZ | O20: =ISNUMBER(SEARCH("xyz", B20)) -> TRUE | S20: 6" MFL5+XYZ | T20: 119403
A21: Method | B21: 105681, 6" LGT | C21: LGT.06 | D21: TD Williamson, Inc | E21: 4/17/2023 1:47:28 PM | F21: Available | G21: 1 | H21: Available | I21: 94810 | J21: No | K21: Available | L21: Yes | M21: =_xlfn.TEXTBEFORE(B21, ",") -> 105681 | N21: =_xlfn.TEXTAFTER(B21, ",") -> 6" LGT | O21: =ISNUMBER(SEARCH("xyz", B21)) -> FALSE | S21: 6" LGT | T21: 105681
A22: Method | B22: 103829, 6" LGT Ammonia | C22: LGT.06 | D22: TD Williamson, Inc | E22: 4/17/2023 1:45:38 PM | F22: Available | G22: 1 | H22: Available | I22: 94826 | J22: No | K22: Available | L22: Yes | M22: =_xlfn.TEXTBEFORE(B22, ",") -> 103829 | N22: =_xlfn.TEXTAFTER(B22, ",") -> 6" LGT Ammonia | O22: =ISNUMBER(SEARCH("xyz", B22)) -> FALSE | S22: 6" LGT Ammonia | T22: 103829
A23: Method | B23: 119785, 6" MFL+DEF | C23: DEF.MFL.06 | D23: TD Williamson, Inc | E23: 5/8/2023 9:16:03 AM | F23: Available | G23: 1 | H23: Available | I23: 96187 | J23: No | K23: Available | L23: Yes | M23: =_xlfn.TEXTBEFORE(B23, ",") -> 119785 | N23: =_xlfn.TEXTAFTER(B23, ",") -> 6" MFL+DEF | O23: =ISNUMBER(SEARCH("xyz", B23)) -> FALSE | S23: 6" MFL+DEF | T23: 119785
A24: Method | B24: 122434, 6" MFL5 | C24: MFL.06 | D24: TD Williamson, Inc | E24: 4/17/2023 1:53:28 PM | F24: Available | G24: 1 | H24: Available | I24: 97562 | J24: No | K24: Available | L24: Yes | M24: =_xlfn.TEXTBEFORE(B24, ",") -> 122434 | N24: =_xlfn.TEXTAFTER(B24, ",") -> 6" MFL5 | O24: =ISNUMBER(SEARCH("xyz", B24)) -> FALSE | S24: 6" MFL5 | T24: 122434
A25: Method | B25: 122975, 6" DEF+XYZ | C25: DEF.XYZ.06 | D25: TD Williamson, Inc | E25: 5/14/2024 10:58:34 AM | F25: Available | G25: 1 | H25: Available | I25: 99033 | J25: No | K25: Available | L25: Yes | M25: =_xlfn.TEXTBEFORE(B25, ",") -> 122975 | N25: =_xlfn.TEXTAFTER(B25, ",") -> 6" DEF+XYZ | O25: =ISNUMBER(SEARCH("xyz", B25)) -> TRUE | S25: 6" DEF+XYZ | T25: 122975
A26: Method | B26: 124750, 6" MFL+DEF (xHD) | C26: DEF.MFL.06 | D26: TD Williamson, Inc | E26: 4/3/2020 6:26:03 AM | F26: Available | G26: 1 | H26: Available | I26: 103640 | J26: No | K26: Available | L26: Yes | M26: =_xlfn.TEXTBEFORE(B26, ",") -> 124750 | N26: =_xlfn.TEXTAFTER(B26, ",") -> 6" MFL+DEF (xHD) | O26: =ISNUMBER(SEARCH("xyz", B26)) -> FALSE | S26: 6" MFL+DEF (xHD) | T26: 124750
A27: Method | B27: 127231, 6" MFL+DEF+XYZ (xHD) | C27: DEF.MFL.XYZ.06 | D27: TD Williamson, Inc | E27: 4/17/2023 1:58:52 PM | F27: Available | G27: 1 | H27: Available | I27: 104636 | J27: No | K27: Available | L27: Yes | M27: =_xlfn.TEXTBEFORE(B27, ",") -> 127231 | N27: =_xlfn.TEXTAFTER(B27, ",") -> 6" MFL+DEF+XYZ (xHD) | O27: =ISNUMBER(SEARCH("xyz", B27)) -> TRUE | S27: 6" MFL+DEF+XYZ (xHD) | T27: 127231
